Workbook

Sheet Resumen Ejecutivo
A1: RESUMEN EJECUTIVO — COSTO / BENEFICIO DE MARKETING 2027 (PLAN AJUSTADO)
A3: 1. Por área
A4: Área | B4: Costo anual | C4: Ingreso anual | D4: Beneficio neto | E4: ROI (%) | F4: ROI (x) | G4: N.º campañas
A5: LANZAMIENTO | B5: ='Reporte Costo-Beneficio'!AY6 | C5: ='Reporte Costo-Beneficio'!AZ6 | D5: =C5-B5 | E5: =IF(B5=0,0,D5/B5) | F5: =IF(B5=0,0,C5/B5) | G5: =COUNTIF(Supuestos!$A$12:$A$22,A5)
A6: PUBLICIDAD DIGITAL | B6: ='Reporte Costo-Beneficio'!AY9 | C6: ='Reporte Costo-Beneficio'!AZ9 | D6: =C6-B6 | E6: =IF(B6=0,0,D6/B6) | F6: =IF(B6=0,0,C6/B6) | G6: =COUNTIF(Supuestos!$A$12:$A$22,A6)
A7: DELIVERY Y FIDELIZACIÓN | B7: ='Reporte Costo-Beneficio'!AY14 | C7: ='Reporte Costo-Beneficio'!AZ14 | D7: =C7-B7 | E7: =IF(B7=0,0,D7/B7) | F7: =IF(B7=0,0,C7/B7) | G7: =COUNTIF(Supuestos!$A$12:$A$22,A7)
A8: FECHAS ESPECIALES | B8: ='Reporte Costo-Beneficio'!AY17 | C8: ='Reporte Costo-Beneficio'!AZ17 | D8: =C8-B8 | E8: =IF(B8=0,0,D8/B8) | F8: =IF(B8=0,0,C8/B8) | G8: =COUNTIF(Supuestos!$A$12:$A$22,A8)
A9: COMUNIDAD Y ALIANZAS | B9: ='Reporte Costo-Beneficio'!AY20 | C9: ='Reporte Costo-Beneficio'!AZ20 | D9: =C9-B9 | E9: =IF(B9=0,0,D9/B9) | F9: =IF(B9=0,0,C9/B9) | G9: =COUNTIF(Supuestos!$A$12:$A$22,A9)
A10: TOTAL GENERAL | B10: =SUM(B5:B9) | C10: =SUM(C5:C9) | D10: =SUM(D5:D9) | E10: =D10/B10 | F10: =C10/B10 | G10: =SUM(G5:G9)
A12: 2. Por campaña (anual)
A13: Área | B13: Campaña | C13: Costo anual | D13: Ingreso anual | E13: Beneficio neto | F13: ROI (%) | G13: ROI (x) | H13: Meses activos | I13: Fechas
A14: =Supuestos!A12 | B14: =Supuestos!B12 | C14: ='Reporte Costo-Beneficio'!AY7 | D14: ='Reporte Costo-Beneficio'!AZ7 | E14: =D14-C14 | F14: =IF(C14=0,0,E14/C14) | G14: =IF(C14=0,0,D14/C14) | H14: =Supuestos!Q12 | I14: =Supuestos!U12
A15: =Supuestos!A13 | B15: =Supuestos!B13 | C15: ='Reporte Costo-Beneficio'!AY8 | D15: ='Reporte Costo-Beneficio'!AZ8 | E15: =D15-C15 | F15: =IF(C15=0,0,E15/C15) | G15: =IF(C15=0,0,D15/C15) | H15: =Supuestos!Q13 | I15: =Supuestos!U13
A16: =Supuestos!A14 | B16: =Supuestos!B14 | C16: ='Reporte Costo-Beneficio'!AY10 | D16: ='Reporte Costo-Beneficio'!AZ10 | E16: =D16-C16 | F16: =IF(C16=0,0,E16/C16) | G16: =IF(C16=0,0,D16/C16) | H16: =Supuestos!Q14 | I16: =Supuestos!U14
A17: =Supuestos!A15 | B17: =Supuestos!B15 | C17: ='Reporte Costo-Beneficio'!AY11 | D17: ='Reporte Costo-Beneficio'!AZ11 | E17: =D17-C17 | F17: =IF(C17=0,0,E17/C17) | G17: =IF(C17=0,0,D17/C17) | H17: =Supuestos!Q15 | I17: =Supuestos!U15
A18: =Supuestos!A16 | B18: =Supuestos!B16 | C18: ='Reporte Costo-Beneficio'!AY12 | D18: ='Reporte Costo-Beneficio'!AZ12 | E18: =D18-C18 | F18: =IF(C18=0,0,E18/C18) | G18: =IF(C18=0,0,D18/C18) | H18: =Supuestos!Q16 | I18: =Supuestos!U16
A19: =Supuestos!A17 | B19: =Supuestos!B17 | C19: ='Reporte Costo-Beneficio'!AY13 | D19: ='Reporte Costo-Beneficio'!AZ13 | E19: =D19-C19 | F19: =IF(C19=0,0,E19/C19) | G19: =IF(C19=0,0,D19/C19) | H19: =Supuestos!Q17 | I19: =Supuestos!U17
A20: =Supuestos!A18 | B20: =Supuestos!B18 | C20: ='Reporte Costo-Beneficio'!AY15 | D20: ='Reporte Costo-Beneficio'!AZ15 | E20: =D20-C20 | F20: =IF(C20=0,0,E20/C20) | G20: =IF(C20=0,0,D20/C20) | H20: =Supuestos!Q18 | I20: =Supuestos!U18
A21: =Supuestos!A19 | B21: =Supuestos!B19 | C21: ='Reporte Costo-Beneficio'!AY16 | D21: ='Reporte Costo-Beneficio'!AZ16 | E21: =D21-C21 | F21: =IF(C21=0,0,E21/C21) | G21: =IF(C21=0,0,D21/C21) | H21: =Supuestos!Q19 | I21: =Supuestos!U19
A22: =Supuestos!A20 | B22: =Supuestos!B20 | C22: ='Reporte Costo-Beneficio'!AY18 | D22: ='Reporte Costo-Beneficio'!AZ18 | E22: =D22-C22 | F22: =IF(C22=0,0,E22/C22) | G22: =IF(C22=0,0,D22/C22) | H22: =Supuestos!Q20 | I22: =Supuestos!U20
A23: =Supuestos!A21 | B23: =Supuestos!B21 | C23: ='Reporte Costo-Beneficio'!AY19 | D23: ='Reporte Costo-Beneficio'!AZ19 | E23: =D23-C23 | F23: =IF(C23=0,0,E23/C23) | G23: =IF(C23=0,0,D23/C23) | H23: =Supuestos!Q21 | I23: =Supuestos!U21
A24: =Supuestos!A22 | B24: =Supuestos!B22 | C24: ='Reporte Costo-Beneficio'!AY21 | D24: ='Reporte Costo-Beneficio'!AZ21 | E24: =D24-C24 | F24: =IF(C24=0,0,E24/C24) | G24: =IF(C24=0,0,D24/C24) | H24: =Supuestos!Q22 | I24: =Supuestos!U22
A25: TOTAL | C25: =SUM(C14:C24) | D25: =SUM(D14:D24) | E25: =SUM(E14:E24) | F25: =E25/C25 | G25: =D25/C25
A27: 3. Por mes
A28: Mes | B28: Costo | C28: Ingreso | D28: Beneficio neto | E28: ROI (%) | F28: N.º campañas activas
A29: Enero | B29: ='Reporte Costo-Beneficio'!C23 | C29: ='Reporte Costo-Beneficio'!D24 | D29: =C29-B29 | E29: =IF(B29=0,0,D29/B29) | F29: =SUM(Supuestos!E12:E22)
A30: Febrero | B30: ='Reporte Costo-Beneficio'!G23 | C30: ='Reporte Costo-Beneficio'!H24 | D30: =C30-B30 | E30: =IF(B30=0,0,D30/B30) | F30: =SUM(Supuestos!F12:F22)
A31: Marzo | B31: ='Reporte Costo-Beneficio'!K23 | C31: ='Reporte Costo-Beneficio'!L24 | D31: =C31-B31 | E31: =IF(B31=0,0,D31/B31) | F31: =SUM(Supuestos!G12:G22)
A32: Abril | B32: ='Reporte Costo-Beneficio'!O23 | C32: ='Reporte Costo-Beneficio'!P24 | D32: =C32-B32 | E32: =IF(B32=0,0,D32/B32) | F32: =SUM(Supuestos!H12:H22)
A33: Mayo | B33: ='Reporte Costo-Beneficio'!S23 | C33: ='Reporte Costo-Beneficio'!T24 | D33: =C33-B33 | E33: =IF(B33=0,0,D33/B33) | F33: =SUM(Supuestos!I12:I22)
A34: Junio | B34: ='Reporte Costo-Beneficio'!W23 | C34: ='Reporte Costo-Beneficio'!X24 | D34: =C34-B34 | E34: =IF(B34=0,0,D34/B34) | F34: =SUM(Supuestos!J12:J22)
A35: Julio | B35: ='Reporte Costo-Beneficio'!AA23 | C35: ='Reporte Costo-Beneficio'!AB24 | D35: =C35-B35 | E35: =IF(B35=0,0,D35/B35) | F35: =SUM(Supuestos!K12:K22)
A36: Agosto | B36: ='Reporte Costo-Beneficio'!AE23 | C36: ='Reporte Costo-Beneficio'!AF24 | D36: =C36-B36 | E36: =IF(B36=0,0,D36/B36) | F36: =SUM(Supuestos!L12:L22)
A37: Septiembre | B37: ='Reporte Costo-Beneficio'!AI23 | C37: ='Reporte Costo-Beneficio'!AJ24 | D37: =C37-B37 | E37: =IF(B37=0,0,D37/B37) | F37: =SUM(Supuestos!M12:M22)
A38: Octubre | B38: ='Reporte Costo-Beneficio'!AM23 | C38: ='Reporte Costo-Beneficio'!AN24 | D38: =C38-B38 | E38: =IF(B38=0,0,D38/B38) | F38: =SUM(Supuestos!N12:N22)
A39: Noviembre | B39: ='Reporte Costo-Beneficio'!AQ23 | C39: ='Reporte Costo-Beneficio'!AR24 | D39: =C39-B39 | E39: =IF(B39=0,0,D39/B39) | F39: =SUM(Supuestos!O12:O22)
A40: Diciembre | B40: ='Reporte Costo-Beneficio'!AU23 | C40: ='Reporte Costo-Beneficio'!AV24 | D40: =C40-B40 | E40: =IF(B40=0,0,D40/B40) | F40: =SUM(Supuestos!P12:P22)
A41: TOTAL | B41: =SUM(B29:B40) | C41: =SUM(C29:C40) | D41: =SUM(D29:D40) | E41: =D41/B41
A43: Mejor mes (beneficio neto): | B43: =INDEX(A29:A40,MATCH(MAX(D29:D40),D29:D40,0))
A44: Campaña con mayor ROI: | B44: =INDEX(B14:B24,MATCH(MAX(F14:F24),F14:F24,0))
...

Sheet Reporte Costo-Beneficio
A1: DÖNER STREET — PLAN DE COSTO / BENEFICIO DE MARKETING 2027 POR CAMPAÑA Y MES (FORECAST)
A4: Área | B4: Campaña | C4: Enero | G4: Febrero | K4: Marzo | O4: Abril | S4: Mayo | W4: Junio | AA4: Julio | AE4: Agosto | AI4: Septiembre | AM4: Octubre | AQ4: Noviembre | AU4: Diciembre | AY4: TOTAL ANUAL
C5: Costo (inversión) | D5: Ingreso (forecast) | E5: Beneficio neto | F5: ROI | G5: Costo (inversión) | H5: Ingreso (forecast) | I5: Beneficio neto | J5: ROI | K5: Costo (inversión) | L5: Ingreso (forecast) | M5: Beneficio neto | N5: ROI | O5: Costo (inversión) | P5: Ingreso (forecast) | Q5: Beneficio neto | R5: ROI | S5: Costo (inversión) | T5: Ingreso (forecast) | U5: Beneficio neto | V5: ROI | W5: Costo (inversión) | X5: Ingreso (forecast) | Y5: Beneficio neto | Z5: ROI | AA5: Costo (inversión) | AB5: Ingreso (forecast) | AC5: Beneficio neto | AD5: ROI | AE5: Costo (inversión) | AF5: Ingreso (forecast) | AG5: Beneficio neto | AH5: ROI | AI5: Costo (inversión) | AJ5: Ingreso (forecast) | AK5: Beneficio neto | AL5: ROI | AM5: Costo (inversión) | AN5: Ingreso (forecast) | AO5: Beneficio neto | AP5: ROI | AQ5: Costo (inversión) | AR5: Ingreso (forecast) | AS5: Beneficio neto | AT5: ROI | AU5: Costo (inversión) | AV5: Ingreso (forecast) | AW5: Beneficio neto | AX5: ROI | AY5: Costo (inversión) | AZ5: Ingreso (forecast) | BA5: Beneficio neto | BB5: ROI
A6: LANZAMIENTO — Total | C6: =SUM(C7:C8) | D6: =SUM(D7:D8) | E6: =D6-C6 | F6: =IF(C6=0,0,E6/C6) | G6: =SUM(G7:G8) | H6: =SUM(H7:H8) | I6: =H6-G6 | J6: =IF(G6=0,0,I6/G6) | K6: =SUM(K7:K8) | L6: =SUM(L7:L8) | M6: =L6-K6 | N6: =IF(K6=0,0,M6/K6) | O6: =SUM(O7:O8) | P6: =SUM(P7:P8) | Q6: =P6-O6 | R6: =IF(O6=0,0,Q6/O6) | S6: =SUM(S7:S8) | T6: =SUM(T7:T8) | U6: =T6-S6 | V6: =IF(S6=0,0,U6/S6) | W6: =SUM(W7:W8) | X6: =SUM(X7:X8) | Y6: =X6-W6 | Z6: =IF(W6=0,0,Y6/W6) | AA6: =SUM(AA7:AA8) | AB6: =SUM(AB7:AB8) | AC6: =AB6-AA6 | AD6: =IF(AA6=0,0,AC6/AA6) | AE6: =SUM(AE7:AE8) | AF6: =SUM(AF7:AF8) | AG6: =AF6-AE6 | AH6: =IF(AE6=0,0,AG6/AE6) | AI6: =SUM(AI7:AI8) | AJ6: =SUM(AJ7:AJ8) | AK6: =AJ6-AI6 | AL6: =IF(AI6=0,0,AK6/AI6) | AM6: =SUM(AM7:AM8) | AN6: =SUM(AN7:AN8) | AO6: =AN6-AM6 | AP6: =IF(AM6=0,0,AO6/AM6) | AQ6: =SUM(AQ7:AQ8) | AR6: =SUM(AR7:AR8) | AS6: =AR6-AQ6 | AT6: =IF(AQ6=0,0,AS6/AQ6) | AU6: =SUM(AU7:AU8) | AV6: =SUM(AV7:AV8) | AW6: =AV6-AU6 | AX6: =IF(AU6=0,0,AW6/AU6) | AY6: =C6+G6+K6+O6+S6+W6+AA6+AE6+AI6+AM6+AQ6+AU6 | AZ6: =D6+H6+L6+P6+T6+X6+AB6+AF6+AJ6+AN6+AR6+AV6 | BA6: =AZ6-AY6 | BB6: =IF(AY6=0,0,BA6/AY6)
A7: LANZAMIENTO | B7: =Supuestos!B12 | C7: =Supuestos!$T12/Supuestos!$Q12*Supuestos!E12 | D7: =Supuestos!$C12/Supuestos!$Q12*Supuestos!E12*Supuestos!$D12*Supuestos!E$7 | E7: =D7-C7 | F7: =IF(C7=0,0,E7/C7) | G7: =Supuestos!$T12/Supuestos!$Q12*Supuestos!F12 | H7: =Supuestos!$C12/Supuestos!$Q12*Supuestos!F12*Supuestos!$D12*Supuestos!F$7 | I7: =H7-G7 | J7: =IF(G7=0,0,I7/G7) | K7: =Supuestos!$T12/Supuestos!$Q12*Supuestos!G12 | L7: =Supuestos!$C12/Supuestos!$Q12*Supuestos!G12*Supuestos!$D12*Supuestos!G$7 | M7: =L7-K7 | N7: =IF(K7=0,0,M7/K7) | O7: =Supuestos!$T12/Supuestos!$Q12*Supuestos!H12 | P7: =Supuestos!$C12/Supuestos!$Q12*Supuestos!H12*Supuestos!$D12*Supuestos!H$7 | Q7: =P7-O7 | R7: =IF(O7=0,0,Q7/O7) | S7: =Supuestos!$T12/Supuestos!$Q12*Supuestos!I12 | T7: =Supuestos!$C12/Supuestos!$Q12*Supuestos!I12*Supuestos!$D12*Supuestos!I$7 | U7: =T7-S7 | V7: =IF(S7=0,0,U7/S7) | W7: =Supuestos!$T12/Supuestos!$Q12*Supuestos!J12 | X7: =Supuestos!$C12/Supuestos!$Q12*Supuestos!J12*Supuestos!$D12*Supuestos!J$7 | Y7: =X7-W7 | Z7: =IF(W7=0,0,Y7/W7) | AA7: =Supuestos!$T12/Supuestos!$Q12*Supuestos!K12 | AB7: =Supuestos!$C12/Supuestos!$Q12*Supuestos!K12*Supuestos!$D12*Supuestos!K$7 | AC7: =AB7-AA7 | AD7: =IF(AA7=0,0,AC7/AA7) | AE7: =Supuestos!$T12/Supuestos!$Q12*Supuestos!L12 | AF7: =Supuestos!$C12/Supuestos!$Q12*Supuestos!L12*Supuestos!$D12*Supuestos!L$7 | AG7: =AF7-AE7 | AH7: =IF(AE7=0,0,AG7/AE7) | AI7: =Supuestos!$T12/Supuestos!$Q12*Supuestos!M12 | AJ7: =Supuestos!$C12/Supuestos!$Q12*Supuestos!M12*Supuestos!$D12*Supuestos!M$7 | AK7: =AJ7-AI7 | AL7: =IF(AI7=0,0,AK7/AI7) | AM7: =Supuestos!$T12/Supuestos!$Q12*Supuestos!N12 | AN7: =Supuestos!$C12/Supuestos!$Q12*Supuestos!N12*Supuestos!$D12*Supuestos!N$7 | AO7: =AN7-AM7 | AP7: =IF(AM7=0,0,AO7/AM7) | AQ7: =Supuestos!$T12/Supuestos!$Q12*Supuestos!O12 | AR7: =Supuestos!$C12/Supuestos!$Q12*Supuestos!O12*Supuestos!$D12*Supuestos!O$7 | AS7: =AR7-AQ7 | AT7: =IF(AQ7=0,0,AS7/AQ7) | AU7: =Supuestos!$T12/Supuestos!$Q12*Supuestos!P12 | AV7: =Supuestos!$C12/Supuestos!$Q12*Supuestos!P12*Supuestos!$D12*Supuestos!P$7 | AW7: =AV7-AU7 | AX7: =IF(AU7=0,0,AW7/AU7) | AY7: =C7+G7+K7+O7+S7+W7+AA7+AE7+AI7+AM7+AQ7+AU7 | AZ7: =D7+H7+L7+P7+T7+X7+AB7+AF7+AJ7+AN7+AR7+AV7 | BA7: =AZ7-AY7 | BB7: =IF(AY7=0,0,BA7/AY7)
A8: LANZAMIENTO | B8: =Supuestos!B13 | C8: =Supuestos!$T13/Supuestos!$Q13*Supuestos!E13 | D8: =Supuestos!$C13/Supuestos!$Q13*Supuestos!E13*Supuestos!$D13*Supuestos!E$7 | E8: =D8-C8 | F8: =IF(C8=0,0,E8/C8) | G8: =Supuestos!$T13/Supuestos!$Q13*Supuestos!F13 | H8: =Supuestos!$C13/Supuestos!$Q13*Supuestos!F13*Supuestos!$D13*Supuestos!F$7 | I8: =H8-G8 | J8: =IF(G8=0,0,I8/G8) | K8: =Supuestos!$T13/Supuestos!$Q13*Supuestos!G13 | L8: =Supuestos!$C13/Supuestos!$Q13*Supuestos!G13*Supuestos!$D13*Supuestos!G$7 | M8: =L8-K8 | N8: =IF(K8=0,0,M8/K8) | O8: =Supuestos!$T13/Supuestos!$Q13*Supuestos!H13 | P8: =Supuestos!$C13/Supuestos!$Q13*Supuestos!H13*Supuestos!$D13*Supuestos!H$7 | Q8: =P8-O8 | R8: =IF(O8=0,0,Q8/O8) | S8: =Supuestos!$T13/Supuestos!$Q13*Supuestos!I13 | T8: =Supuestos!$C13/Supuestos!$Q13*Supuestos!I13*Supuestos!$D13*Supuestos!I$7 | U8: =T8-S8 | V8: =IF(S8=0,0,U8/S8) | W8: =Supuestos!$T13/Supuestos!$Q13*Supuestos!J13 | X8: =Supuestos!$C13/Supuestos!$Q13*Supuestos!J13*Supuestos!$D13*Supuestos!J$7 | Y8: =X8-W8 | Z8: =IF(W8=0,0,Y8/W8) | AA8: =Supuestos!$T13/Supuestos!$Q13*Supuestos!K13 | AB8: =Supuestos!$C13/Supuestos!$Q13*Supuestos!K13*Supuestos!$D13*Supuestos!K$7 | AC8: =AB8-AA8 | AD8: =IF(AA8=0,0,AC8/AA8) | AE8: =Supuestos!$T13/Supuestos!$Q13*Supuestos!L13 | AF8: =Supuestos!$C13/Supuestos!$Q13*Supuestos!L13*Supuestos!$D13*Supuestos!L$7 | AG8: =AF8-AE8 | AH8: =IF(AE8=0,0,AG8/AE8) | AI8: =Supuestos!$T13/Supuestos!$Q13*Supuestos!M13 | AJ8: =Supuestos!$C13/Supuestos!$Q13*Supuestos!M13*Supuestos!$D13*Supuestos!M$7 | AK8: =AJ8-AI8 | AL8: =IF(AI8=0,0,AK8/AI8) | AM8: =Supuestos!$T13/Supuestos!$Q13*Supuestos!N13 | AN8: =Supuestos!$C13/Supuestos!$Q13*Supuestos!N13*Supuestos!$D13*Supuestos!N$7 | AO8: =AN8-AM8 | AP8: =IF(AM8=0,0,AO8/AM8) | AQ8: =Supuestos!$T13/Supuestos!$Q13*Supuestos!O13 | AR8: =Supuestos!$C13/Supuestos!$Q13*Supuestos!O13*Supuestos!$D13*Supuestos!O$7 | AS8: =AR8-AQ8 | AT8: =IF(AQ8=0,0,AS8/AQ8) | AU8: =Supuestos!$T13/Supuestos!$Q13*Supuestos!P13 | AV8: =Supuestos!$C13/Supuestos!$Q13*Supuestos!P13*Supuestos!$D13*Supuestos!P$7 | AW8: =AV8-AU8 | AX8: =IF(AU8=0,0,AW8/AU8) | AY8: =C8+G8+K8+O8+S8+W8+AA8+AE8+AI8+AM8+AQ8+AU8 | AZ8: =D8+H8+L8+P8+T8+X8+AB8+AF8+AJ8+AN8+AR8+AV8 | BA8: =AZ8-AY8 | BB8: =IF(AY8=0,0,BA8/AY8)
A9: PUBLICIDAD DIGITAL — Total | C9: =SUM(C10:C13) | D9: =SUM(D10:D13) | E9: =D9-C9 | F9: =IF(C9=0,0,E9/C9) | G9: =SUM(G10:G13) | H9: =SUM(H10:H13) | I9: =H9-G9 | J9: =IF(G9=0,0,I9/G9) | K9: =SUM(K10:K13) | L9: =SUM(L10:L13) | M9: =L9-K9 | N9: =IF(K9=0,0,M9/K9) | O9: =SUM(O10:O13) | P9: =SUM(P10:P13) | Q9: =P9-O9 | R9: =IF(O9=0,0,Q9/O9) | S9: =SUM(S10:S13) | T9: =SUM(T10:T13) | U9: =T9-S9 | V9: =IF(S9=0,0,U9/S9) | W9: =SUM(W10:W13) | X9: =SUM(X10:X13) | Y9: =X9-W9 | Z9: =IF(W9=0,0,Y9/W9) | AA9: =SUM(AA10:AA13) | AB9: =SUM(AB10:AB13) | AC9: =AB9-AA9 | AD9: =IF(AA9=0,0,AC9/AA9) | AE9: =SUM(AE10:AE13) | AF9: =SUM(AF10:AF13) | AG9: =AF9-AE9 | AH9: =IF(AE9=0,0,AG9/AE9) | AI9: =SUM(AI10:AI13) | AJ9: =SUM(AJ10:AJ13) | AK9: =AJ9-AI9 | AL9: =IF(AI9=0,0,AK9/AI9) | AM9: =SUM(AM10:AM13) | AN9: =SUM(AN10:AN13) | AO9: =AN9-AM9 | AP9: =IF(AM9=0,0,AO9/AM9) | AQ9: =SUM(AQ10:AQ13) | AR9: =SUM(AR10:AR13) | AS9: =AR9-AQ9 | AT9: =IF(AQ9=0,0,AS9/AQ9) | AU9: =SUM(AU10:AU13) | AV9: =SUM(AV10:AV13) | AW9: =AV9-AU9 | AX9: =IF(AU9=0,0,AW9/AU9) | AY9: =C9+G9+K9+O9+S9+W9+AA9+AE9+AI9+AM9+AQ9+AU9 | AZ9: =D9+H9+L9+P9+T9+X9+AB9+AF9+AJ9+AN9+AR9+AV9 | BA9: =AZ9-AY9 | BB9: =IF(AY9=0,0,BA9/AY9)
A10: PUBLICIDAD DIGITAL | B10: =Supuestos!B14 | C10: =Supuestos!$T14/Supuestos!$Q14*Supuestos!E14 | D10: =Supuestos!$C14/Supuestos!$Q14*Supuestos!E14*Supuestos!$D14*Supuestos!E$7 | E10: =D10-C10 | F10: =IF(C10=0,0,E10/C10) | G10: =Supuestos!$T14/Supuestos!$Q14*Supuestos!F14 | H10: =Supuestos!$C14/Supuestos!$Q14*Supuestos!F14*Supuestos!$D14*Supuestos!F$7 | I10: =H10-G10 | J10: =IF(G10=0,0,I10/G10) | K10: =Supuestos!$T14/Supuestos!$Q14*Supuestos!G14 | L10: =Supuestos!$C14/Supuestos!$Q14*Supuestos!G14*Supuestos!$D14*Supuestos!G$7 | M10: =L10-K10 | N10: =IF(K10=0,0,M10/K10) | O10: =Supuestos!$T14/Supuestos!$Q14*Supuestos!H14 | P10: =Supuestos!$C14/Supuestos!$Q14*Supuestos!H14*Supuestos!$D14*Supuestos!H$7 | Q10: =P10-O10 | R10: =IF(O10=0,0,Q10/O10) | S10: =Supuestos!$T14/Supuestos!$Q14*Supuestos!I14 | T10: =Supuestos!$C14/Supuestos!$Q14*Supuestos!I14*Supuestos!$D14*Supuestos!I$7 | U10: =T10-S10 | V10: =IF(S10=0,0,U10/S10) | W10: =Supuestos!$T14/Supuestos!$Q14*Supuestos!J14 | X10: =Supuestos!$C14/Supuestos!$Q14*Supuestos!J14*Supuestos!$D14*Supuestos!J$7 | Y10: =X10-W10 | Z10: =IF(W10=0,0,Y10/W10) | AA10: =Supuestos!$T14/Supuestos!$Q14*Supuestos!K14 | AB10: =Supuestos!$C14/Supuestos!$Q14*Supuestos!K14*Supuestos!$D14*Supuestos!K$7 | AC10: =AB10-AA10 | AD10: =IF(AA10=0,0,AC10/AA10) | AE10: =Supuestos!$T14/Supuestos!$Q14*Supuestos!L14 | AF10: =Supuestos!$C14/Supuestos!$Q14*Supuestos!L14*Supuestos!$D14*Supuestos!L$7 | AG10: =AF10-AE10 | AH10: =IF(AE10=0,0,AG10/AE10) | AI10: =Supuestos!$T14/Supuestos!$Q14*Supuestos!M14 | AJ10: =Supuestos!$C14/Supuestos!$Q14*Supuestos!M14*Supuestos!$D14*Supuestos!M$7 | AK10: =AJ10-AI10 | AL10: =IF(AI10=0,0,AK10/AI10) | AM10: =Supuestos!$T14/Supuestos!$Q14*Supuestos!N14 | AN10: =Supuestos!$C14/Supuestos!$Q14*Supuestos!N14*Supuestos!$D14*Supuestos!N$7 | AO10: =AN10-AM10 | AP10: =IF(AM10=0,0,AO10/AM10) | AQ10: =Supuestos!$T14/Supuestos!$Q14*Supuestos!O14 | AR10: =Supuestos!$C14/Supuestos!$Q14*Supuestos!O14*Supuestos!$D14*Supuestos!O$7 | AS10: =AR10-AQ10 | AT10: =IF(AQ10=0,0,AS10/AQ10) | AU10: =Supuestos!$T14/Supuestos!$Q14*Supuestos!P14 | AV10: =Supuestos!$C14/Supuestos!$Q14*Supuestos!P14*Supuestos!$D14*Supuestos!P$7 | AW10: =AV10-AU10 | AX10: =IF(AU10=0,0,AW10/AU10) | AY10: =C10+G10+K10+O10+S10+W10+AA10+AE10+AI10+AM10+AQ10+AU10 | AZ10: =D10+H10+L10+P10+T10+X10+AB10+AF10+AJ10+AN10+AR10+AV10 | BA10: =AZ10-AY10 | BB10: =IF(AY10=0,0,BA10/AY10)
A11: PUBLICIDAD DIGITAL | B11: =Supuestos!B15 | C11: =Supuestos!$T15/Supuestos!$Q15*Supuestos!E15 | D11: =Supuestos!$C15/Supuestos!$Q15*Supuestos!E15*Supuestos!$D15*Supuestos!E$7 | E11: =D11-C11 | F11: =IF(C11=0,0,E11/C11) | G11: =Supuestos!$T15/Supuestos!$Q15*Supuestos!F15 | H11: =Supuestos!$C15/Supuestos!$Q15*Supuestos!F15*Supuestos!$D15*Supuestos!F$7 | I11: =H11-G11 | J11: =IF(G11=0,0,I11/G11) | K11: =Supuestos!$T15/Supuestos!$Q15*Supuestos!G15 | L11: =Supuestos!$C15/Supuestos!$Q15*Supuestos!G15*Supuestos!$D15*Supuestos!G$7 | M11: =L11-K11 | N11: =IF(K11=0,0,M11/K11) | O11: =Supuestos!$T15/Supuestos!$Q15*Supuestos!H15 | P11: =Supuestos!$C15/Supuestos!$Q15*Supuestos!H15*Supuestos!$D15*Supuestos!H$7 | Q11: =P11-O11 | R11: =IF(O11=0,0,Q11/O11) | S11: =Supuestos!$T15/Supuestos!$Q15*Supuestos!I15 | T11: =Supuestos!$C15/Supuestos!$Q15*Supuestos!I15*Supuestos!$D15*Supuestos!I$7 | U11: =T11-S11 | V11: =IF(S11=0,0,U11/S11) | W11: =Supuestos!$T15/Supuestos!$Q15*Supuestos!J15 | X11: =Supuestos!$C15/Supuestos!$Q15*Supuestos!J15*Supuestos!$D15*Supuestos!J$7 | Y11: =X11-W11 | Z11: =IF(W11=0,0,Y11/W11) | AA11: =Supuestos!$T15/Supuestos!$Q15*Supuestos!K15 | AB11: =Supuestos!$C15/Supuestos!$Q15*Supuestos!K15*Supuestos!$D15*Supuestos!K$7 | AC11: =AB11-AA11 | AD11: =IF(AA11=0,0,AC11/AA11) | AE11: =Supuestos!$T15/Supuestos!$Q15*Supuestos!L15 | AF11: =Supuestos!$C15/Supuestos!$Q15*Supuestos!L15*Supuestos!$D15*Supuestos!L$7 | AG11: =AF11-AE11 | AH11: =IF(AE11=0,0,AG11/AE11) | AI11: =Supuestos!$T15/Supuestos!$Q15*Supuestos!M15 | AJ11: =Supuestos!$C15/Supuestos!$Q15*Supuestos!M15*Supuestos!$D15*Supuestos!M$7 | AK11: =AJ11-AI11 | AL11: =IF(AI11=0,0,AK11/AI11) | AM11: =Supuestos!$T15/Supuestos!$Q15*Supuestos!N15 | AN11: =Supuestos!$C15/Supuestos!$Q15*Supuestos!N15*Supuestos!$D15*Supuestos!N$7 | AO11: =AN11-AM11 | AP11: =IF(AM11=0,0,AO11/AM11) | AQ11: =Supuestos!$T15/Supuestos!$Q15*Supuestos!O15 | AR11: =Supuestos!$C15/Supuestos!$Q15*Supuestos!O15*Supuestos!$D15*Supuestos!O$7 | AS11: =AR11-AQ11 | AT11: =IF(AQ11=0,0,AS11/AQ11) | AU11: =Supuestos!$T15/Supuestos!$Q15*Supuestos!P15 | AV11: =Supuestos!$C15/Supuestos!$Q15*Supuestos!P15*Supuestos!$D15*Supuestos!P$7 | AW11: =AV11-AU11 | AX11: =IF(AU11=0,0,AW11/AU11) | AY11: =C11+G11+K11+O11+S11+W11+AA11+AE11+AI11+AM11+AQ11+AU11 | AZ11: =D11+H11+L11+P11+T11+X11+AB11+AF11+AJ11+AN11+AR11+AV11 | BA11: =AZ11-AY11 | BB11: =IF(AY11=0,0,BA11/AY11)
A12: PUBLICIDAD DIGITAL | B12: =Supuestos!B16 | C12: =Supuestos!$T16/Supuestos!$Q16*Supuestos!E16 | D12: =Supuestos!$C16/Supuestos!$Q16*Supuestos!E16*Supuestos!$D16*Supuestos!E$7 | E12: =D12-C12 | F12: =IF(C12=0,0,E12/C12) | G12: =Supuestos!$T16/Supuestos!$Q16*Supuestos!F16 | H12: =Supuestos!$C16/Supuestos!$Q16*Supuestos!F16*Supuestos!$D16*Supuestos!F$7 | I12: =H12-G12 | J12: =IF(G12=0,0,I12/G12) | K12: =Supuestos!$T16/Supuestos!$Q16*Supuestos!G16 | L12: =Supuestos!$C16/Supuestos!$Q16*Supuestos!G16*Supuestos!$D16*Supuestos!G$7 | M12: =L12-K12 | N12: =IF(K12=0,0,M12/K12) | O12: =Supuestos!$T16/Supuestos!$Q16*Supuestos!H16 | P12: =Supuestos!$C16/Supuestos!$Q16*Supuestos!H16*Supuestos!$D16*Supuestos!H$7 | Q12: =P12-O12 | R12: =IF(O12=0,0,Q12/O12) | S12: =Supuestos!$T16/Supuestos!$Q16*Supuestos!I16 | T12: =Supuestos!$C16/Supuestos!$Q16*Supuestos!I16*Supuestos!$D16*Supuestos!I$7 | U12: =T12-S12 | V12: =IF(S12=0,0,U12/S12) | W12: =Supuestos!$T16/Supuestos!$Q16*Supuestos!J16 | X12: =Supuestos!$C16/Supuestos!$Q16*Supuestos!J16*Supuestos!$D16*Supuestos!J$7 | Y12: =X12-W12 | Z12: =IF(W12=0,0,Y12/W12) | AA12: =Supuestos!$T16/Supuestos!$Q16*Supuestos!K16 | AB12: =Supuestos!$C16/Supuestos!$Q16*Supuestos!K16*Supuestos!$D16*Supuestos!K$7 | AC12: =AB12-AA12 | AD12: =IF(AA12=0,0,AC12/AA12) | AE12: =Supuestos!$T16/Supuestos!$Q16*Supuestos!L16 | AF12: =Supuestos!$C16/Supuestos!$Q16*Supuestos!L16*Supuestos!$D16*Supuestos!L$7 | AG12: =AF12-AE12 | AH12: =IF(AE12=0,0,AG12/AE12) | AI12: =Supuestos!$T16/Supuestos!$Q16*Supuestos!M16 | AJ12: =Supuestos!$C16/Supuestos!$Q16*Supuestos!M16*Supuestos!$D16*Supuestos!M$7 | AK12: =AJ12-AI12 | AL12: =IF(AI12=0,0,AK12/AI12) | AM12: =Supuestos!$T16/Supuestos!$Q16*Supuestos!N16 | AN12: =Supuestos!$C16/Supuestos!$Q16*Supuestos!N16*Supuestos!$D16*Supuestos!N$7 | AO12: =AN12-AM12 | AP12: =IF(AM12=0,0,AO12/AM12) | AQ12: =Supuestos!$T16/Supuestos!$Q16*Supuestos!O16 | AR12: =Supuestos!$C16/Supuestos!$Q16*Supuestos!O16*Supuestos!$D16*Supuestos!O$7 | AS12: =AR12-AQ12 | AT12: =IF(AQ12=0,0,AS12/AQ12) | AU12: =Supuestos!$T16/Supuestos!$Q16*Supuestos!P16 | AV12: =Supuestos!$C16/Supuestos!$Q16*Supuestos!P16*Supuestos!$D16*Supuestos!P$7 | AW12: =AV12-AU12 | AX12: =IF(AU12=0,0,AW12/AU12) | AY12: =C12+G12+K12+O12+S12+W12+AA12+AE12+AI12+AM12+AQ12+AU12 | AZ12: =D12+H12+L12+P12+T12+X12+AB12+AF12+AJ12+AN12+AR12+AV12 | BA12: =AZ12-AY12 | BB12: =IF(AY12=0,0,BA12/AY12)
A13: PUBLICIDAD DIGITAL | B13: =Supuestos!B17 | C13: =Supuestos!$T17/Supuestos!$Q17*Supuestos!E17 | D13: =Supuestos!$C17/Supuestos!$Q17*Supuestos!E17*Supuestos!$D17*Supuestos!E$7 | E13: =D13-C13 | F13: =IF(C13=0,0,E13/C13) | G13: =Supuestos!$T17/Supuestos!$Q17*Supuestos!F17 | H13: =Supuestos!$C17/Supuestos!$Q17*Supuestos!F17*Supuestos!$D17*Supuestos!F$7 | I13: =H13-G13 | J13: =IF(G13=0,0,I13/G13) | K13: =Supuestos!$T17/Supuestos!$Q17*Supuestos!G17 | L13: =Supuestos!$C17/Supuestos!$Q17*Supuestos!G17*Supuestos!$D17*Supuestos!G$7 | M13: =L13-K13 | N13: =IF(K13=0,0,M13/K13) | O13: =Supuestos!$T17/Supuestos!$Q17*Supuestos!H17 | P13: =Supuestos!$C17/Supuestos!$Q17*Supuestos!H17*Supuestos!$D17*Supuestos!H$7 | Q13: =P13-O13 | R13: =IF(O13=0,0,Q13/O13) | S13: =Supuestos!$T17/Supuestos!$Q17*Supuestos!I17 | T13: =Supuestos!$C17/Supuestos!$Q17*Supuestos!I17*Supuestos!$D17*Supuestos!I$7 | U13: =T13-S13 | V13: =IF(S13=0,0,U13/S13) | W13: =Supuestos!$T17/Supuestos!$Q17*Supuestos!J17 | X13: =Supuestos!$C17/Supuestos!$Q17*Supuestos!J17*Supuestos!$D17*Supuestos!J$7 | Y13: =X13-W13 | Z13: =IF(W13=0,0,Y13/W13) | AA13: =Supuestos!$T17/Supuestos!$Q17*Supuestos!K17 | AB13: =Supuestos!$C17/Supuestos!$Q17*Supuestos!K17*Supuestos!$D17*Supuestos!K$7 | AC13: =AB13-AA13 | AD13: =IF(AA13=0,0,AC13/AA13) | AE13: =Supuestos!$T17/Supuestos!$Q17*Supuestos!L17 | AF13: =Supuestos!$C17/Supuestos!$Q17*Supuestos!L17*Supuestos!$D17*Supuestos!L$7 | AG13: =AF13-AE13 | AH13: =IF(AE13=0,0,AG13/AE13) | AI13: =Supuestos!$T17/Supuestos!$Q17*Supuestos!M17 | AJ13: =Supuestos!$C17/Supuestos!$Q17*Supuestos!M17*Supuestos!$D17*Supuestos!M$7 | AK13: =AJ13-AI13 | AL13: =IF(AI13=0,0,AK13/AI13) | AM13: =Supuestos!$T17/Supuestos!$Q17*Supuestos!N17 | AN13: =Supuestos!$C17/Supuestos!$Q17*Supuestos!N17*Supuestos!$D17*Supuestos!N$7 | AO13: =AN13-AM13 | AP13: =IF(AM13=0,0,AO13/AM13) | AQ13: =Supuestos!$T17/Supuestos!$Q17*Supuestos!O17 | AR13: =Supuestos!$C17/Supuestos!$Q17*Supuestos!O17*Supuestos!$D17*Supuestos!O$7 | AS13: =AR13-AQ13 | AT13: =IF(AQ13=0,0,AS13/AQ13) | AU13: =Supuestos!$T17/Supuestos!$Q17*Supuestos!P17 | AV13: =Supuestos!$C17/Supuestos!$Q17*Supuestos!P17*Supuestos!$D17*Supuestos!P$7 | AW13: =AV13-AU13 | AX13: =IF(AU13=0,0,AW13/AU13) | AY13: =C13+G13+K13+O13+S13+W13+AA13+AE13+AI13+AM13+AQ13+AU13 | AZ13: =D13+H13+L13+P13+T13+X13+AB13+AF13+AJ13+AN13+AR13+AV13 | BA13: =AZ13-AY13 | BB13: =IF(AY13=0,0,BA13/AY13)
A14: DELIVERY Y FIDELIZACIÓN — Total | C14: =SUM(C15:C16) | D14: =SUM(D15:D16) | E14: =D14-C14 | F14: =IF(C14=0,0,E14/C14) | G14: =SUM(G15:G16) | H14: =SUM(H15:H16) | I14: =H14-G14 | J14: =IF(G14=0,0,I14/G14) | K14: =SUM(K15:K16) | L14: =SUM(L15:L16) | M14: =L14-K14 | N14: =IF(K14=0,0,M14/K14) | O14: =SUM(O15:O16) | P14: =SUM(P15:P16) | Q14: =P14-O14 | R14: =IF(O14=0,0,Q14/O14) | S14: =SUM(S15:S16) | T14: =SUM(T15:T16) | U14: =T14-S14 | V14: =IF(S14=0,0,U14/S14) | W14: =SUM(W15:W16) | X14: =SUM(X15:X16) | Y14: =X14-W14 | Z14: =IF(W14=0,0,Y14/W14) | AA14: =SUM(AA15:AA16) | AB14: =SUM(AB15:AB16) | AC14: =AB14-AA14 | AD14: =IF(AA14=0,0,AC14/AA14) | AE14: =SUM(AE15:AE16) | AF14: =SUM(AF15:AF16) | AG14: =AF14-AE14 | AH14: =IF(AE14=0,0,AG14/AE14) | AI14: =SUM(AI15:AI16) | AJ14: =SUM(AJ15:AJ16) | AK14: =AJ14-AI14 | AL14: =IF(AI14=0,0,AK14/AI14) | AM14: =SUM(AM15:AM16) | AN14: =SUM(AN15:AN16) | AO14: =AN14-AM14 | AP14: =IF(AM14=0,0,AO14/AM14) | AQ14: =SUM(AQ15:AQ16) | AR14: =SUM(AR15:AR16) | AS14: =AR14-AQ14 | AT14: =IF(AQ14=0,0,AS14/AQ14) | AU14: =SUM(AU15:AU16) | AV14: =SUM(AV15:AV16) | AW14: =AV14-AU14 | AX14: =IF(AU14=0,0,AW14/AU14) | AY14: =C14+G14+K14+O14+S14+W14+AA14+AE14+AI14+AM14+AQ14+AU14 | AZ14: =D14+H14+L14+P14+T14+X14+AB14+AF14+AJ14+AN14+AR14+AV14 | BA14: =AZ14-AY14 | BB14: =IF(AY14=0,0,BA14/AY14)
A15: DELIVERY Y FIDELIZACIÓN | B15: =Supuestos!B18 | C15: =Supuestos!$T18/Supuestos!$Q18*Supuestos!E18 | D15: =Supuestos!$C18/Supuestos!$Q18*Supuestos!E18*Supuestos!$D18*Supuestos!E$7 | E15: =D15-C15 | F15: =IF(C15=0,0,E15/C15) | G15: =Supuestos!$T18/Supuestos!$Q18*Supuestos!F18 | H15: =Supuestos!$C18/Supuestos!$Q18*Supuestos!F18*Supuestos!$D18*Supuestos!F$7 | I15: =H15-G15 | J15: =IF(G15=0,0,I15/G15) | K15: =Supuestos!$T18/Supuestos!$Q18*Supuestos!G18 | L15: =Supuestos!$C18/Supuestos!$Q18*Supuestos!G18*Supuestos!$D18*Supuestos!G$7 | M15: =L15-K15 | N15: =IF(K15=0,0,M15/K15) | O15: =Supuestos!$T18/Supuestos!$Q18*Supuestos!H18 | P15: =Supuestos!$C18/Supuestos!$Q18*Supuestos!H18*Supuestos!$D18*Supuestos!H$7 | Q15: =P15-O15 | R15: =IF(O15=0,0,Q15/O15) | S15: =Supuestos!$T18/Supuestos!$Q18*Supuestos!I18 | T15: =Supuestos!$C18/Supuestos!$Q18*Supuestos!I18*Supuestos!$D18*Supuestos!I$7 | U15: =T15-S15 | V15: =IF(S15=0,0,U15/S15) | W15: =Supuestos!$T18/Supuestos!$Q18*Supuestos!J18 | X15: =Supuestos!$C18/Supuestos!$Q18*Supuestos!J18*Supuestos!$D18*Supuestos!J$7 | Y15: =X15-W15 | Z15: =IF(W15=0,0,Y15/W15) | AA15: =Supuestos!$T18/Supuestos!$Q18*Supuestos!K18 | AB15: =Supuestos!$C18/Supuestos!$Q18*Supuestos!K18*Supuestos!$D18*Supuestos!K$7 | AC15: =AB15-AA15 | AD15: =IF(AA15=0,0,AC15/AA15) | AE15: =Supuestos!$T18/Supuestos!$Q18*Supuestos!L18 | AF15: =Supuestos!$C18/Supuestos!$Q18*Supuestos!L18*Supuestos!$D18*Supuestos!L$7 | AG15: =AF15-AE15 | AH15: =IF(AE15=0,0,AG15/AE15) | AI15: =Supuestos!$T18/Supuestos!$Q18*Supuestos!M18 | AJ15: =Supuestos!$C18/Supuestos!$Q18*Supuestos!M18*Supuestos!$D18*Supuestos!M$7 | AK15: =AJ15-AI15 | AL15: =IF(AI15=0,0,AK15/AI15) | AM15: =Supuestos!$T18/Supuestos!$Q18*Supuestos!N18 | AN15: =Supuestos!$C18/Supuestos!$Q18*Supuestos!N18*Supuestos!$D18*Supuestos!N$7 | AO15: =AN15-AM15 | AP15: =IF(AM15=0,0,AO15/AM15) | AQ15: =Supuestos!$T18/Supuestos!$Q18*Supuestos!O18 | AR15: =Supuestos!$C18/Supuestos!$Q18*Supuestos!O18*Supuestos!$D18*Supuestos!O$7 | AS15: =AR15-AQ15 | AT15: =IF(AQ15=0,0,AS15/AQ15) | AU15: =Supuestos!$T18/Supuestos!$Q18*Supuestos!P18 | AV15: =Supuestos!$C18/Supuestos!$Q18*Supuestos!P18*Supuestos!$D18*Supuestos!P$7 | AW15: =AV15-AU15 | AX15: =IF(AU15=0,0,AW15/AU15) | AY15: =C15+G15+K15+O15+S15+W15+AA15+AE15+AI15+AM15+AQ15+AU15 | AZ15: =D15+H15+L15+P15+T15+X15+AB15+AF15+AJ15+AN15+AR15+AV15 | BA15: =AZ15-AY15 | BB15: =IF(AY15=0,0,BA15/AY15)
A16: DELIVERY Y FIDELIZACIÓN | B16: =Supuestos!B19 | C16: =Supuestos!$T19/Supuestos!$Q19*Supuestos!E19 | D16: =Supuestos!$C19/Supuestos!$Q19*Supuestos!E19*Supuestos!$D19*Supuestos!E$7 | E16: =D16-C16 | F16: =IF(C16=0,0,E16/C16) | G16: =Supuestos!$T19/Supuestos!$Q19*Supuestos!F19 | H16: =Supuestos!$C19/Supuestos!$Q19*Supuestos!F19*Supuestos!$D19*Supuestos!F$7 | I16: =H16-G16 | J16: =IF(G16=0,0,I16/G16) | K16: =Supuestos!$T19/Supuestos!$Q19*Supuestos!G19 | L16: =Supuestos!$C19/Supuestos!$Q19*Supuestos!G19*Supuestos!$D19*Supuestos!G$7 | M16: =L16-K16 | N16: =IF(K16=0,0,M16/K16) | O16: =Supuestos!$T19/Supuestos!$Q19*Supuestos!H19 | P16: =Supuestos!$C19/Supuestos!$Q19*Supuestos!H19*Supuestos!$D19*Supuestos!H$7 | Q16: =P16-O16 | R16: =IF(O16=0,0,Q16/O16) | S16: =Supuestos!$T19/Supuestos!$Q19*Supuestos!I19 | T16: =Supuestos!$C19/Supuestos!$Q19*Supuestos!I19*Supuestos!$D19*Supuestos!I$7 | U16: =T16-S16 | V16: =IF(S16=0,0,U16/S16) | W16: =Supuestos!$T19/Supuestos!$Q19*Supuestos!J19 | X16: =Supuestos!$C19/Supuestos!$Q19*Supuestos!J19*Supuestos!$D19*Supuestos!J$7 | Y16: =X16-W16 | Z16: =IF(W16=0,0,Y16/W16) | AA16: =Supuestos!$T19/Supuestos!$Q19*Supuestos!K19 | AB16: =Supuestos!$C19/Supuestos!$Q19*Supuestos!K19*Supuestos!$D19*Supuestos!K$7 | AC16: =AB16-AA16 | AD16: =IF(AA16=0,0,AC16/AA16) | AE16: =Supuestos!$T19/Supuestos!$Q19*Supuestos!L19 | AF16: =Supuestos!$C19/Supuestos!$Q19*Supuestos!L19*Supuestos!$D19*Supuestos!L$7 | AG16: =AF16-AE16 | AH16: =IF(AE16=0,0,AG16/AE16) | AI16: =Supuestos!$T19/Supuestos!$Q19*Supuestos!M19 | AJ16: =Supuestos!$C19/Supuestos!$Q19*Supuestos!M19*Supuestos!$D19*Supuestos!M$7 | AK16: =AJ16-AI16 | AL16: =IF(AI16=0,0,AK16/AI16) | AM16: =Supuestos!$T19/Supuestos!$Q19*Supuestos!N19 | AN16: =Supuestos!$C19/Supuestos!$Q19*Supuestos!N19*Supuestos!$D19*Supuestos!N$7 | AO16: =AN16-AM16 | AP16: =IF(AM16=0,0,AO16/AM16) | AQ16: =Supuestos!$T19/Supuestos!$Q19*Supuestos!O19 | AR16: =Supuestos!$C19/Supuestos!$Q19*Supuestos!O19*Supuestos!$D19*Supuestos!O$7 | AS16: =AR16-AQ16 | AT16: =IF(AQ16=0,0,AS16/AQ16) | AU16: =Supuestos!$T19/Supuestos!$Q19*Supuestos!P19 | AV16: =Supuestos!$C19/Supuestos!$Q19*Supuestos!P19*Supuestos!$D19*Supuestos!P$7 | AW16: =AV16-AU16 | AX16: =IF(AU16=0,0,AW16/AU16) | AY16: =C16+G16+K16+O16+S16+W16+AA16+AE16+AI16+AM16+AQ16+AU16 | AZ16: =D16+H16+L16+P16+T16+X16+AB16+AF16+AJ16+AN16+AR16+AV16 | BA16: =AZ16-AY16 | BB16: =IF(AY16=0,0,BA16/AY16)
A17: FECHAS ESPECIALES — Total | C17: =SUM(C18:C19) | D17: =SUM(D18:D19) | E17: =D17-C17 | F17: =IF(C17=0,0,E17/C17) | G17: =SUM(G18:G19) | H17: =SUM(H18:H19) | I17: =H17-G17 | J17: =IF(G17=0,0,I17/G17) | K17: =SUM(K18:K19) | L17: =SUM(L18:L19) | M17: =L17-K17 | N17: =IF(K17=0,0,M17/K17) | O17: =SUM(O18:O19) | P17: =SUM(P18:P19) | Q17: =P17-O17 | R17: =IF(O17=0,0,Q17/O17) | S17: =SUM(S18:S19) | T17: =SUM(T18:T19) | U17: =T17-S17 | V17: =IF(S17=0,0,U17/S17) | W17: =SUM(W18:W19) | X17: =SUM(X18:X19) | Y17: =X17-W17 | Z17: =IF(W17=0,0,Y17/W17) | AA17: =SUM(AA18:AA19) | AB17: =SUM(AB18:AB19) | AC17: =AB17-AA17 | AD17: =IF(AA17=0,0,AC17/AA17) | AE17: =SUM(AE18:AE19) | AF17: =SUM(AF18:AF19) | AG17: =AF17-AE17 | AH17: =IF(AE17=0,0,AG17/AE17) | AI17: =SUM(AI18:AI19) | AJ17: =SUM(AJ18:AJ19) | AK17: =AJ17-AI17 | AL17: =IF(AI17=0,0,AK17/AI17) | AM17: =SUM(AM18:AM19) | AN17: =SUM(AN18:AN19) | AO17: =AN17-AM17 | AP17: =IF(AM17=0,0,AO17/AM17) | AQ17: =SUM(AQ18:AQ19) | AR17: =SUM(AR18:AR19) | AS17: =AR17-AQ17 | AT17: =IF(AQ17=0,0,AS17/AQ17) | AU17: =SUM(AU18:AU19) | AV17: =SUM(AV18:AV19) | AW17: =AV17-AU17 | AX17: =IF(AU17=0,0,AW17/AU17) | AY17: =C17+G17+K17+O17+S17+W17+AA17+AE17+AI17+AM17+AQ17+AU17 | AZ17: =D17+H17+L17+P17+T17+X17+AB17+AF17+AJ17+AN17+AR17+AV17 | BA17: =AZ17-AY17 | BB17: =IF(AY17=0,0,BA17/AY17)
A18: FECHAS ESPECIALES | B18: =Supuestos!B20 | C18: =Supuestos!$T20/Supuestos!$Q20*Supuestos!E20 | D18: =Supuestos!$C20/Supuestos!$Q20*Supuestos!E20*Supuestos!$D20*Supuestos!E$7 | E18: =D18-C18 | F18: =IF(C18=0,0,E18/C18) | G18: =Supuestos!$T20/Supuestos!$Q20*Supuestos!F20 | H18: =Supuestos!$C20/Supuestos!$Q20*Supuestos!F20*Supuestos!$D20*Supuestos!F$7 | I18: =H18-G18 | J18: =IF(G18=0,0,I18/G18) | K18: =Supuestos!$T20/Supuestos!$Q20*Supuestos!G20 | L18: =Supuestos!$C20/Supuestos!$Q20*Supuestos!G20*Supuestos!$D20*Supuestos!G$7 | M18: =L18-K18 | N18: =IF(K18=0,0,M18/K18) | O18: =Supuestos!$T20/Supuestos!$Q20*Supuestos!H20 | P18: =Supuestos!$C20/Supuestos!$Q20*Supuestos!H20*Supuestos!$D20*Supuestos!H$7 | Q18: =P18-O18 | R18: =IF(O18=0,0,Q18/O18) | S18: =Supuestos!$T20/Supuestos!$Q20*Supuestos!I20 | T18: =Supuestos!$C20/Supuestos!$Q20*Supuestos!I20*Supuestos!$D20*Supuestos!I$7 | U18: =T18-S18 | V18: =IF(S18=0,0,U18/S18) | W18: =Supuestos!$T20/Supuestos!$Q20*Supuestos!J20 | X18: =Supuestos!$C20/Supuestos!$Q20*Supuestos!J20*Supuestos!$D20*Supuestos!J$7 | Y18: =X18-W18 | Z18: =IF(W18=0,0,Y18/W18) | AA18: =Supuestos!$T20/Supuestos!$Q20*Supuestos!K20 | AB18: =Supuestos!$C20/Supuestos!$Q20*Supuestos!K20*Supuestos!$D20*Supuestos!K$7 | AC18: =AB18-AA18 | AD18: =IF(AA18=0,0,AC18/AA18) | AE18: =Supuestos!$T20/Supuestos!$Q20*Supuestos!L20 | AF18: =Supuestos!$C20/Supuestos!$Q20*Supuestos!L20*Supuestos!$D20*Supuestos!L$7 | AG18: =AF18-AE18 | AH18: =IF(AE18=0,0,AG18/AE18) | AI18: =Supuestos!$T20/Supuestos!$Q20*Supuestos!M20 | AJ18: =Supuestos!$C20/Supuestos!$Q20*Supuestos!M20*Supuestos!$D20*Supuestos!M$7 | AK18: =AJ18-AI18 | AL18: =IF(AI18=0,0,AK18/AI18) | AM18: =Supuestos!$T20/Supuestos!$Q20*Supuestos!N20 | AN18: =Supuestos!$C20/Supuestos!$Q20*Supuestos!N20*Supuestos!$D20*Supuestos!N$7 | AO18: =AN18-AM18 | AP18: =IF(AM18=0,0,AO18/AM18) | AQ18: =Supuestos!$T20/Supuestos!$Q20*Supuestos!O20 | AR18: =Supuestos!$C20/Supuestos!$Q20*Supuestos!O20*Supuestos!$D20*Supuestos!O$7 | AS18: =AR18-AQ18 | AT18: =IF(AQ18=0,0,AS18/AQ18) | AU18: =Supuestos!$T20/Supuestos!$Q20*Supuestos!P20 | AV18: =Supuestos!$C20/Supuestos!$Q20*Supuestos!P20*Supuestos!$D20*Supuestos!P$7 | AW18: =AV18-AU18 | AX18: =IF(AU18=0,0,AW18/AU18) | AY18: =C18+G18+K18+O18+S18+W18+AA18+AE18+AI18+AM18+AQ18+AU18 | AZ18: =D18+H18+L18+P18+T18+X18+AB18+AF18+AJ18+AN18+AR18+AV18 | BA18: =AZ18-AY18 | BB18: =IF(AY18=0,0,BA18/AY18)
A19: FECHAS ESPECIALES | B19: =Supuestos!B21 | C19: =Supuestos!$T21/Supuestos!$Q21*Supuestos!E21 | D19: =Supuestos!$C21/Supuestos!$Q21*Supuestos!E21*Supuestos!$D21*Supuestos!E$7 | E19: =D19-C19 | F19: =IF(C19=0,0,E19/C19) | G19: =Supuestos!$T21/Supuestos!$Q21*Supuestos!F21 | H19: =Supuestos!$C21/Supuestos!$Q21*Supuestos!F21*Supuestos!$D21*Supuestos!F$7 | I19: =H19-G19 | J19: =IF(G19=0,0,I19/G19) | K19: =Supuestos!$T21/Supuestos!$Q21*Supuestos!G21 | L19: =Supuestos!$C21/Supuestos!$Q21*Supuestos!G21*Supuestos!$D21*Supuestos!G$7 | M19: =L19-K19 | N19: =IF(K19=0,0,M19/K19) | O19: =Supuestos!$T21/Supuestos!$Q21*Supuestos!H21 | P19: =Supuestos!$C21/Supuestos!$Q21*Supuestos!H21*Supuestos!$D21*Supuestos!H$7 | Q19: =P19-O19 | R19: =IF(O19=0,0,Q19/O19) | S19: =Supuestos!$T21/Supuestos!$Q21*Supuestos!I21 | T19: =Supuestos!$C21/Supuestos!$Q21*Supuestos!I21*Supuestos!$D21*Supuestos!I$7 | U19: =T19-S19 | V19: =IF(S19=0,0,U19/S19) | W19: =Supuestos!$T21/Supuestos!$Q21*Supuestos!J21 | X19: =Supuestos!$C21/Supuestos!$Q21*Supuestos!J21*Supuestos!$D21*Supuestos!J$7 | Y19: =X19-W19 | Z19: =IF(W19=0,0,Y19/W19) | AA19: =Supuestos!$T21/Supuestos!$Q21*Supuestos!K21 | AB19: =Supuestos!$C21/Supuestos!$Q21*Supuestos!K21*Supuestos!$D21*Supuestos!K$7 | AC19: =AB19-AA19 | AD19: =IF(AA19=0,0,AC19/AA19) | AE19: =Supuestos!$T21/Supuestos!$Q21*Supuestos!L21 | AF19: =Supuestos!$C21/Supuestos!$Q21*Supuestos!L21*Supuestos!$D21*Supuestos!L$7 | AG19: =AF19-AE19 | AH19: =IF(AE19=0,0,AG19/AE19) | AI19: =Supuestos!$T21/Supuestos!$Q21*Supuestos!M21 | AJ19: =Supuestos!$C21/Supuestos!$Q21*Supuestos!M21*Supuestos!$D21*Supuestos!M$7 | AK19: =AJ19-AI19 | AL19: =IF(AI19=0,0,AK19/AI19) | AM19: =Supuestos!$T21/Supuestos!$Q21*Supuestos!N21 | AN19: =Supuestos!$C21/Supuestos!$Q21*Supuestos!N21*Supuestos!$D21*Supuestos!N$7 | AO19: =AN19-AM19 | AP19: =IF(AM19=0,0,AO19/AM19) | AQ19: =Supuestos!$T21/Supuestos!$Q21*Supuestos!O21 | AR19: =Supuestos!$C21/Supuestos!$Q21*Supuestos!O21*Supuestos!$D21*Supuestos!O$7 | AS19: =AR19-AQ19 | AT19: =IF(AQ19=0,0,AS19/AQ19) | AU19: =Supuestos!$T21/Supuestos!$Q21*Supuestos!P21 | AV19: =Supuestos!$C21/Supuestos!$Q21*Supuestos!P21*Supuestos!$D21*Supuestos!P$7 | AW19: =AV19-AU19 | AX19: =IF(AU19=0,0,AW19/AU19) | AY19: =C19+G19+K19+O19+S19+W19+AA19+AE19+AI19+AM19+AQ19+AU19 | AZ19: =D19+H19+L19+P19+T19+X19+AB19+AF19+AJ19+AN19+AR19+AV19 | BA19: =AZ19-AY19 | BB19: =IF(AY19=0,0,BA19/AY19)
A20: COMUNIDAD Y ALIANZAS — Total | C20: =SUM(C21:C21) | D20: =SUM(D21:D21) | E20: =D20-C20 | F20: =IF(C20=0,0,E20/C20) | G20: =SUM(G21:G21) | H20: =SUM(H21:H21) | I20: =H20-G20 | J20: =IF(G20=0,0,I20/G20) | K20: =SUM(K21:K21) | L20: =SUM(L21:L21) | M20: =L20-K20 | N20: =IF(K20=0,0,M20/K20) | O20: =SUM(O21:O21) | P20: =SUM(P21:P21) | Q20: =P20-O20 | R20: =IF(O20=0,0,Q20/O20) | S20: =SUM(S21:S21) | T20: =SUM(T21:T21) | U20: =T20-S20 | V20: =IF(S20=0,0,U20/S20) | W20: =SUM(W21:W21) | X20: =SUM(X21:X21) | Y20: =X20-W20 | Z20: =IF(W20=0,0,Y20/W20) | AA20: =SUM(AA21:AA21) | AB20: =SUM(AB21:AB21) | AC20: =AB20-AA20 | AD20: =IF(AA20=0,0,AC20/AA20) | AE20: =SUM(AE21:AE21) | AF20: =SUM(AF21:AF21) | AG20: =AF20-AE20 | AH20: =IF(AE20=0,0,AG20/AE20) | AI20: =SUM(AI21:AI21) | AJ20: =SUM(AJ21:AJ21) | AK20: =AJ20-AI20 | AL20: =IF(AI20=0,0,AK20/AI20) | AM20: =SUM(AM21:AM21) | AN20: =SUM(AN21:AN21) | AO20: =AN20-AM20 | AP20: =IF(AM20=0,0,AO20/AM20) | AQ20: =SUM(AQ21:AQ21) | AR20: =SUM(AR21:AR21) | AS20: =AR20-AQ20 | AT20: =IF(AQ20=0,0,AS20/AQ20) | AU20: =SUM(AU21:AU21) | AV20: =SUM(AV21:AV21) | AW20: =AV20-AU20 | AX20: =IF(AU20=0,0,AW20/AU20) | AY20: =C20+G20+K20+O20+S20+W20+AA20+AE20+AI20+AM20+AQ20+AU20 | AZ20: =D20+H20+L20+P20+T20+X20+AB20+AF20+AJ20+AN20+AR20+AV20 | BA20: =AZ20-AY20 | BB20: =IF(AY20=0,0,BA20/AY20)
A21: COMUNIDAD Y ALIANZAS | B21: =Supuestos!B22 | C21: =Supuestos!$T22/Supuestos!$Q22*Supuestos!E22 | D21: =Supuestos!$C22/Supuestos!$Q22*Supuestos!E22*Supuestos!$D22*Supuestos!E$7 | E21: =D21-C21 | F21: =IF(C21=0,0,E21/C21) | G21: =Supuestos!$T22/Supuestos!$Q22*Supuestos!F22 | H21: =Supuestos!$C22/Supuestos!$Q22*Supuestos!F22*Supuestos!$D22*Supuestos!F$7 | I21: =H21-G21 | J21: =IF(G21=0,0,I21/G21) | K21: =Supuestos!$T22/Supuestos!$Q22*Supuestos!G22 | L21: =Supuestos!$C22/Supuestos!$Q22*Supuestos!G22*Supuestos!$D22*Supuestos!G$7 | M21: =L21-K21 | N21: =IF(K21=0,0,M21/K21) | O21: =Supuestos!$T22/Supuestos!$Q22*Supuestos!H22 | P21: =Supuestos!$C22/Supuestos!$Q22*Supuestos!H22*Supuestos!$D22*Supuestos!H$7 | Q21: =P21-O21 | R21: =IF(O21=0,0,Q21/O21) | S21: =Supuestos!$T22/Supuestos!$Q22*Supuestos!I22 | T21: =Supuestos!$C22/Supuestos!$Q22*Supuestos!I22*Supuestos!$D22*Supuestos!I$7 | U21: =T21-S21 | V21: =IF(S21=0,0,U21/S21) | W21: =Supuestos!$T22/Supuestos!$Q22*Supuestos!J22 | X21: =Supuestos!$C22/Supuestos!$Q22*Supuestos!J22*Supuestos!$D22*Supuestos!J$7 | Y21: =X21-W21 | Z21: =IF(W21=0,0,Y21/W21) | AA21: =Supuestos!$T22/Supuestos!$Q22*Supuestos!K22 | AB21: =Supuestos!$C22/Supuestos!$Q22*Supuestos!K22*Supuestos!$D22*Supuestos!K$7 | AC21: =AB21-AA21 | AD21: =IF(AA21=0,0,AC21/AA21) | AE21: =Supuestos!$T22/Supuestos!$Q22*Supuestos!L22 | AF21: =Supuestos!$C22/Supuestos!$Q22*Supuestos!L22*Supuestos!$D22*Supuestos!L$7 | AG21: =AF21-AE21 | AH21: =IF(AE21=0,0,AG21/AE21) | AI21: =Supuestos!$T22/Supuestos!$Q22*Supuestos!M22 | AJ21: =Supuestos!$C22/Supuestos!$Q22*Supuestos!M22*Supuestos!$D22*Supuestos!M$7 | AK21: =AJ21-AI21 | AL21: =IF(AI21=0,0,AK21/AI21) | AM21: =Supuestos!$T22/Supuestos!$Q22*Supuestos!N22 | AN21: =Supuestos!$C22/Supuestos!$Q22*Supuestos!N22*Supuestos!$D22*Supuestos!N$7 | AO21: =AN21-AM21 | AP21: =IF(AM21=0,0,AO21/AM21) | AQ21: =Supuestos!$T22/Supuestos!$Q22*Supuestos!O22 | AR21: =Supuestos!$C22/Supuestos!$Q22*Supuestos!O22*Supuestos!$D22*Supuestos!O$7 | AS21: =AR21-AQ21 | AT21: =IF(AQ21=0,0,AS21/AQ21) | AU21: =Supuestos!$T22/Supuestos!$Q22*Supuestos!P22 | AV21: =Supuestos!$C22/Supuestos!$Q22*Supuestos!P22*Supuestos!$D22*Supuestos!P$7 | AW21: =AV21-AU21 | AX21: =IF(AU21=0,0,AW21/AU21) | AY21: =C21+G21+K21+O21+S21+W21+AA21+AE21+AI21+AM21+AQ21+AU21 | AZ21: =D21+H21+L21+P21+T21+X21+AB21+AF21+AJ21+AN21+AR21+AV21 | BA21: =AZ21-AY21 | BB21: =IF(AY21=0,0,BA21/AY21)
A23: TOTAL COSTO MARKETING (INVERSIÓN) | C23: =C6+C9+C14+C17+C20 | G23: =G6+G9+G14+G17+G20 | K23: =K6+K9+K14+K17+K20 | O23: =O6+O9+O14+O17+O20 | S23: =S6+S9+S14+S17+S20 | W23: =W6+W9+W14+W17+W20 | AA23: =AA6+AA9+AA14+AA17+AA20 | AE23: =AE6+AE9+AE14+AE17+AE20 | AI23: =AI6+AI9+AI14+AI17+AI20 | AM23: =AM6+AM9+AM14+AM17+AM20 | AQ23: =AQ6+AQ9+AQ14+AQ17+AQ20 | AU23: =AU6+AU9+AU14+AU17+AU20 | AY23: =AY6+AY9+AY14+AY17+AY20
A24: TOTAL INGRESO (FORECAST) | D24: =D6+D9+D14+D17+D20 | H24: =H6+H9+H14+H17+H20 | L24: =L6+L9+L14+L17+L20 | P24: =P6+P9+P14+P17+P20 | T24: =T6+T9+T14+T17+T20 | X24: =X6+X9+X14+X17+X20 | AB24: =AB6+AB9+AB14+AB17+AB20 | AF24: =AF6+AF9+AF14+AF17+AF20 | AJ24: =AJ6+AJ9+AJ14+AJ17+AJ20 | AN24: =AN6+AN9+AN14+AN17+AN20 | AR24: =AR6+AR9+AR14+AR17+AR20 | AV24: =AV6+AV9+AV14+AV17+AV20 | AZ24: =AZ6+AZ9+AZ14+AZ17+AZ20
A25: TOTAL BENEFICIO NETO | E25: =D24-C23 | I25: =H24-G23 | M25: =L24-K23 | Q25: =P24-O23 | U25: =T24-S23 | Y25: =X24-W23 | AC25: =AB24-AA23 | AG25: =AF24-AE23 | AK25: =AJ24-AI23 | AO25: =AN24-AM23 | AS25: =AR24-AQ23 | AW25: =AV24-AU23 | BA25: =AZ24-AY23
A26: ROI DEL MES | F26: =IF(C23=0,0,E25/C23) | J26: =IF(G23=0,0,I25/G23) | N26: =IF(K23=0,0,M25/K23) | R26: =IF(O23=0,0,Q25/O23) | V26: =IF(S23=0,0,U25/S23) | Z26: =IF(W23=0,0,Y25/W23) | AD26: =IF(AA23=0,0,AC25/AA23) | AH26: =IF(AE23=0,0,AG25/AE23) | AL26: =IF(AI23=0,0,AK25/AI23) | AP26: =IF(AM23=0,0,AO25/AM23) | AT26: =IF(AQ23=0,0,AS25/AQ23) | AX26: =IF(AU23=0,0,AW25/AU23) | BB26: =IF(AY23=0,0,BA25/AY23)
A27: MÚLTIPLO INGRESO / COSTO (x) | F27: =IF(C23=0,0,D24/C23) | J27: =IF(G23=0,0,H24/G23) | N27: =IF(K23=0,0,L24/K23) | R27: =IF(O23=0,0,P24/O23) | V27: =IF(S23=0,0,T24/S23) | Z27: =IF(W23=0,0,X24/W23) | AD27: =IF(AA23=0,0,AB24/AA23) | AH27: =IF(AE23=0,0,AF24/AE23) | AL27: =IF(AI23=0,0,AJ24/AI23) | AP27: =IF(AM23=0,0,AN24/AM23) | AT27: =IF(AQ23=0,0,AR24/AQ23) | AX27: =IF(AU23=0,0,AV24/AU23) | BB27: =IF(AY23=0,0,AZ24/AY23)
A29: Control vs. Supuestos: | C29: =IF(ABS(AY23-Supuestos!T23)<1,"OK ✓ cuadra con el presupuesto","REVISAR")

Sheet Supuestos
A1: SUPUESTOS Y PRESUPUESTO DE MARKETING — DÖNER STREET 2027 (PLAN AJUSTADO, 11 CAMPAÑAS)
C3: 1800000
A5: Índice de estacionalidad mensual (multiplicador de demanda esperado)
A6: Mes | E6: Ene | F6: Feb | G6: Mar | H6: Abr | I6: May | J6: Jun | K6: Jul | L6: Ago | M6: Sep | N6: Oct | O6: Nov | P6: Dic
A7: Índice | E7: 1.2 | F7: 1.15 | G7: 0.9 | H7: 0.85 | I7: 1.05 | J7: 0.95 | K7: 1 | L7: 1.05 | M7: 1.1 | N7: 1.1 | O7: 1.15 | P7: 1.3
A10: Presupuesto y supuestos por campaña
A11: Área | B11: Campaña | C11: Inversión en medios (COP) | D11: ROAS esperado (x) | E11: Ene | F11: Feb | G11: Mar | H11: Abr | I11: May | J11: Jun | K11: Jul | L11: Ago | M11: Sep | N11: Oct | O11: Nov | P11: Dic | Q11: Meses activos | R11: Agencia (1/0) | S11: Honorario (COP) | T11: Costo total (COP) | U11: Fechas (plan 2027)
A12: LANZAMIENTO | B12: Prensa y Redes (Teaser + PR + Promo apertura) | C12: 3000000 | D12: 3 | E12: 1 | F12: 0 | G12: 0 | H12: 0 | I12: 0 | J12: 0 | K12: 0 | L12: 0 | M12: 0 | N12: 0 | O12: 0 | P12: 0 | Q12: =SUM(E12:P12) | R12: 1 | S12: =R12*$C$3 | T12: =C12+S12 | U12: 4-25 ene
A13: LANZAMIENTO | B13: Volantes, degustaciones y garantía de satisfacción | C13: 2000000 | D13: 3.5 | E13: 1 | F13: 1 | G13: 0 | H13: 0 | I13: 0 | J13: 0 | K13: 0 | L13: 0 | M13: 0 | N13: 0 | O13: 0 | P13: 0 | Q13: =SUM(E13:P13) | R13: 0 | S13: =R13*$C$3 | T13: =C13+S13 | U13: 18 ene-1 feb
A14: PUBLICIDAD DIGITAL | B14: Contenido orgánico IG/TikTok/Facebook | C14: 2800000 | D14: 2.5 | E14: 1 | F14: 1 | G14: 1 | H14: 1 | I14: 1 | J14: 1 | K14: 1 | L14: 1 | M14: 1 | N14: 1 | O14: 1 | P14: 1 | Q14: =SUM(E14:P14) | R14: 1 | S14: =R14*$C$3 | T14: =C14+S14 | U14: 4 ene-31 dic (mar y vie)
A15: PUBLICIDAD DIGITAL | B15: Google Business Profile (SEO local) | C15: 1200000 | D15: 6 | E15: 1 | F15: 1 | G15: 1 | H15: 1 | I15: 1 | J15: 1 | K15: 1 | L15: 1 | M15: 1 | N15: 1 | O15: 1 | P15: 1 | Q15: =SUM(E15:P15) | R15: 0 | S15: =R15*$C$3 | T15: =C15+S15 | U15: 4 ene-31 dic
A16: PUBLICIDAD DIGITAL | B16: Meta Ads pagado (geo-segmentado) | C16: 24000000 | D16: 4 | E16: 1 | F16: 1 | G16: 1 | H16: 1 | I16: 1 | J16: 1 | K16: 1 | L16: 1 | M16: 1 | N16: 1 | O16: 1 | P16: 1 | Q16: =SUM(E16:P16) | R16: 0 | S16: =R16*$C$3 | T16: =C16+S16 | U16: 18 ene-31 dic
A17: PUBLICIDAD DIGITAL | B17: QR en empaques/recibos + referidos | C17: 8000000 | D17: 5 | E17: 0 | F17: 1 | G17: 1 | H17: 1 | I17: 1 | J17: 1 | K17: 1 | L17: 1 | M17: 1 | N17: 1 | O17: 1 | P17: 1 | Q17: =SUM(E17:P17) | R17: 0 | S17: =R17*$C$3 | T17: =C17+S17 | U17: 15 feb-31 dic
A18: DELIVERY Y FIDELIZACIÓN | B18: Almuerzos corporativos (pedidos por WhatsApp) | C18: 4000000 | D18: 4.2 | E18: 0 | F18: 0 | G18: 1 | H18: 1 | I18: 1 | J18: 1 | K18: 1 | L18: 1 | M18: 1 | N18: 1 | O18: 1 | P18: 1 | Q18: =SUM(E18:P18) | R18: 0 | S18: =R18*$C$3 | T18: =C18+S18 | U18: 15 mar-31 dic
A19: DELIVERY Y FIDELIZACIÓN | B19: Refiere y gana (papas gratis) | C19: 2000000 | D19: 4.5 | E19: 0 | F19: 0 | G19: 0 | H19: 1 | I19: 1 | J19: 1 | K19: 1 | L19: 0 | M19: 0 | N19: 0 | O19: 0 | P19: 0 | Q19: =SUM(E19:P19) | R19: 0 | S19: =R19*$C$3 | T19: =C19+S19 | U19: 12 abr-5 jul
A20: FECHAS ESPECIALES | B20: San Valentín (Comparte un Döner) | C20: 2500000 | D20: 4 | E20: 0 | F20: 1 | G20: 0 | H20: 0 | I20: 0 | J20: 0 | K20: 0 | L20: 0 | M20: 0 | N20: 0 | O20: 0 | P20: 0 | Q20: =SUM(E20:P20) | R20: 1 | S20: =R20*$C$3 | T20: =C20+S20 | U20: 8-15 feb
A21: FECHAS ESPECIALES | B21: Navidad y fin de año (Party Pack) | C21: 3500000 | D21: 5 | E21: 0 | F21: 0 | G21: 0 | H21: 0 | I21: 0 | J21: 0 | K21: 0 | L21: 0 | M21: 0 | N21: 0 | O21: 0 | P21: 1 | Q21: =SUM(E21:P21) | R21: 1 | S21: =R21*$C$3 | T21: =C21+S21 | U21: 13-27 dic
A22: COMUNIDAD Y ALIANZAS | B22: Semana de bienvenida universitaria | C22: 2000000 | D22: 3 | E22: 0 | F22: 1 | G22: 0 | H22: 0 | I22: 0 | J22: 0 | K22: 0 | L22: 1 | M22: 0 | N22: 0 | O22: 0 | P22: 0 | Q22: =SUM(E22:P22) | R22: 0 | S22: =R22*$C$3 | T22: =C22+S22 | U22: 1-8 feb y 2-9 ago
A23: TOTAL | B23: Presupuesto anual de marketing | C23: =SUM(C12:C22) | R23: =SUM(R12:R22) | S23: =SUM(S12:S22) | T23: =SUM(T12:T22)
