Workbook

Sheet Ventas por Producto 2026
A1: VENTAS POR PRODUCTO 2026 — Döner Street
A2: Celdas azules = datos de entrada (unidades y precio de la tabla de productos). Todo lo demás se calcula.
A4: Producto | B4: Participación (% unidades) | C4: Unidades vendidas (año) | D4: Precio de venta (COP) | E4: Ventas brutas (COP) | F4: Participación (% ventas) | G4: Costo materia prima unitario | H4: Costo materia prima total | I4: Margen bruto unitario
A5: Small Döner | B5: =C5/$C$11 -> 0.080008855 | C5: 3614 | D5: 17100 | E5: =C5*D5 -> 61799400 | F5: =E5/$E$11 -> 0.05096292 | G5: =ROUND(D5*'Supuestos y Notas'!$B$27,0) -> 9468 | H5: =C5*G5 -> 34217352 | I5: =D5-G5 -> 7632
A6: Small Döner Combo | B6: =C6/$C$11 -> 0.1 | C6: 4517 | D6: 23200 | E6: =C6*D6 -> 104794400 | F6: =E6/$E$11 -> 0.086418778 | G6: =ROUND(D6*'Supuestos y Notas'!$B$27,0) -> 12846 | H6: =C6*G6 -> 58025382 | I6: =D6-G6 -> 10354
A7: Medium Döner | B7: =C7/$C$11 -> 0.11999114 | C7: 5420 | D7: 21900 | E7: =C7*D7 -> 118698000 | F7: =E7/$E$11 -> 0.097884392 | G7: =ROUND(D7*'Supuestos y Notas'!$B$27,0) -> 12126 | H7: =C7*G7 -> 65722920 | I7: =D7-G7 -> 9774
A8: Medium Döner Combo | B8: =C8/$C$11 -> 0.44998893 | C8: 20326 | D8: 28400 | E8: =C8*D8 -> 577258400 | F8: =E8/$E$11 -> 0.47603656 | G8: =ROUND(D8*'Supuestos y Notas'!$B$27,0) -> 15725 | H8: =C8*G8 -> 319626350 | I8: =D8-G8 -> 12675
A9: Large Döner | B9: =C9/$C$11 -> 0.1 | C9: 4517 | D9: 26800 | E9: =C9*D9 -> 121055600 | F9: =E9/$E$11 -> 0.099828588 | G9: =ROUND(D9*'Supuestos y Notas'!$B$27,0) -> 14839 | H9: =C9*G9 -> 67027763 | I9: =D9-G9 -> 11961
A10: Large Döner Combo | B10: =C10/$C$11 -> 0.15001107 | C10: 6776 | D10: 33800 | E10: =C10*D10 -> 229028800 | F10: =E10/$E$11 -> 0.18886877 | G10: =ROUND(D10*'Supuestos y Notas'!$B$27,0) -> 18715 | H10: =C10*G10 -> 126812840 | I10: =D10-G10 -> 15085
A11: Total | B11: =SUM(B5:B10) -> 1 | C11: =SUM(C5:C10) -> 45170 | D11: =E11/C11 -> 26846.017 | E11: =SUM(E5:E10) -> 1212634600 | F11: =SUM(F5:F10) -> 1 | G11: =H11/C11 -> 14864.57 | H11: =SUM(H5:H10) -> 671432607 | I11: =D11-G11 -> 11981.448
A12: En la fila Total, "Precio" y "Costo unitario" son promedios ponderados.
A14: ESTACIONALIDAD 2026 (calendario original) | B14: Jan | C14: Feb | D14: Mar | E14: Apr | F14: May | G14: Jun | H14: Jul | I14: Aug | J14: Sep | K14: Oct | L14: Nov | M14: Dec | N14: Total 2026
A15: Unidades del calendario de temporadas 2026 | B15: 2640 | C15: 4200 | D15: 3770 | E15: 4500 | F15: 4650 | G15: 2970 | H15: 2190 | I15: 4590 | J15: 4500 | K15: 4650 | L15: 4440 | M15: 2190 | N15: =SUM(B15:M15) -> 45290
A16: % del año vendido en el mes | B16: =B15/$N$15 -> 0.058291013 | C16: =C15/$N$15 -> 0.092735703 | D16: =D15/$N$15 -> 0.083241334 | E16: =E15/$N$15 -> 0.099359682 | F16: =F15/$N$15 -> 0.10267167 | G16: =G15/$N$15 -> 0.06557739 | H16: =H15/$N$15 -> 0.048355045 | I16: =I15/$N$15 -> 0.10134688 | ... N16: =N15/$N$15 -> 1
A18: UNIDADES VENDIDAS POR MES | B18: Jan | C18: Feb | D18: Mar | E18: Apr | F18: May | G18: Jun | H18: Jul | I18: Aug | J18: Sep | K18: Oct | L18: Nov | M18: Dec | N18: Total 2026
A19: Small Döner | B19: =ROUND($C$5*B$16,0) -> 211 | C19: =ROUND($C$5*C$16,0) -> 335 | D19: =ROUND($C$5*D$16,0) -> 301 | E19: =ROUND($C$5*E$16,0) -> 359 | F19: =ROUND($C$5*F$16,0) -> 371 | G19: =ROUND($C$5*G$16,0) -> 237 | H19: =ROUND($C$5*H$16,0) -> 175 | I19: =ROUND($C$5*I$16,0) -> 366 | ... L19: =ROUND($C$5*L$16,0) -> 354 | M19: =$C$5-SUM(B19:L19) -> 175 | N19: =SUM(B19:M19) -> 3614
A20: Small Döner Combo | B20: =ROUND($C$6*B$16,0) -> 263 | C20: =ROUND($C$6*C$16,0) -> 419 | D20: =ROUND($C$6*D$16,0) -> 376 | E20: =ROUND($C$6*E$16,0) -> 449 | F20: =ROUND($C$6*F$16,0) -> 464 | G20: =ROUND($C$6*G$16,0) -> 296 | H20: =ROUND($C$6*H$16,0) -> 218 | I20: =ROUND($C$6*I$16,0) -> 458 | ... L20: =ROUND($C$6*L$16,0) -> 443 | M20: =$C$6-SUM(B20:L20) -> 218 | N20: =SUM(B20:M20) -> 4517
A21: Medium Döner | B21: =ROUND($C$7*B$16,0) -> 316 | C21: =ROUND($C$7*C$16,0) -> 503 | D21: =ROUND($C$7*D$16,0) -> 451 | E21: =ROUND($C$7*E$16,0) -> 539 | F21: =ROUND($C$7*F$16,0) -> 556 | G21: =ROUND($C$7*G$16,0) -> 355 | H21: =ROUND($C$7*H$16,0) -> 262 | I21: =ROUND($C$7*I$16,0) -> 549 | ... L21: =ROUND($C$7*L$16,0) -> 531 | M21: =$C$7-SUM(B21:L21) -> 263 | N21: =SUM(B21:M21) -> 5420
A22: Medium Döner Combo | B22: =ROUND($C$8*B$16,0) -> 1185 | C22: =ROUND($C$8*C$16,0) -> 1885 | D22: =ROUND($C$8*D$16,0) -> 1692 | E22: =ROUND($C$8*E$16,0) -> 2020 | F22: =ROUND($C$8*F$16,0) -> 2087 | G22: =ROUND($C$8*G$16,0) -> 1333 | H22: =ROUND($C$8*H$16,0) -> 983 | I22: =ROUND($C$8*I$16,0) -> 2060 | ... L22: =ROUND($C$8*L$16,0) -> 1993 | M22: =$C$8-SUM(B22:L22) -> 981 | N22: =SUM(B22:M22) -> 20326
A23: Large Döner | B23: =ROUND($C$9*B$16,0) -> 263 | C23: =ROUND($C$9*C$16,0) -> 419 | D23: =ROUND($C$9*D$16,0) -> 376 | E23: =ROUND($C$9*E$16,0) -> 449 | F23: =ROUND($C$9*F$16,0) -> 464 | G23: =ROUND($C$9*G$16,0) -> 296 | H23: =ROUND($C$9*H$16,0) -> 218 | I23: =ROUND($C$9*I$16,0) -> 458 | ... L23: =ROUND($C$9*L$16,0) -> 443 | M23: =$C$9-SUM(B23:L23) -> 218 | N23: =SUM(B23:M23) -> 4517
A24: Large Döner Combo | B24: =ROUND($C$10*B$16,0) -> 395 | C24: =ROUND($C$10*C$16,0) -> 628 | D24: =ROUND($C$10*D$16,0) -> 564 | E24: =ROUND($C$10*E$16,0) -> 673 | F24: =ROUND($C$10*F$16,0) -> 696 | G24: =ROUND($C$10*G$16,0) -> 444 | H24: =ROUND($C$10*H$16,0) -> 328 | I24: =ROUND($C$10*I$16,0) -> 687 | ... L24: =ROUND($C$10*L$16,0) -> 664 | M24: =$C$10-SUM(B24:L24) -> 328 | N24: =SUM(B24:M24) -> 6776
A25: Total unidades | B25: =SUM(B19:B24) -> 2633 | C25: =SUM(C19:C24) -> 4189 | D25: =SUM(D19:D24) -> 3760 | E25: =SUM(E19:E24) -> 4489 | F25: =SUM(F19:F24) -> 4638 | G25: =SUM(G19:G24) -> 2961 | H25: =SUM(H19:H24) -> 2184 | I25: =SUM(I19:I24) -> 4578 | ... N25: =SUM(N19:N24) -> 45170
A27: VENTAS BRUTAS POR MES (COP) | B27: Jan | C27: Feb | D27: Mar | E27: Apr | F27: May | G27: Jun | H27: Jul | I27: Aug | J27: Sep | K27: Oct | L27: Nov | M27: Dec | N27: Total 2026
A28: Small Döner | B28: =B19*$D$5 -> 3608100 | C28: =C19*$D$5 -> 5728500 | D28: =D19*$D$5 -> 5147100 | E28: =E19*$D$5 -> 6138900 | F28: =F19*$D$5 -> 6344100 | G28: =G19*$D$5 -> 4052700 | H28: =H19*$D$5 -> 2992500 | I28: =I19*$D$5 -> 6258600 | ... M28: =M19*$D$5 -> 2992500 | N28: =SUM(B28:M28) -> 61799400
A29: Small Döner Combo | B29: =B20*$D$6 -> 6101600 | C29: =C20*$D$6 -> 9720800 | D29: =D20*$D$6 -> 8723200 | E29: =E20*$D$6 -> 10416800 | F29: =F20*$D$6 -> 10764800 | G29: =G20*$D$6 -> 6867200 | H29: =H20*$D$6 -> 5057600 | I29: =I20*$D$6 -> 10625600 | ... M29: =M20*$D$6 -> 5057600 | N29: =SUM(B29:M29) -> 104794400
A30: Medium Döner | B30: =B21*$D$7 -> 6920400 | C30: =C21*$D$7 -> 11015700 | D30: =D21*$D$7 -> 9876900 | E30: =E21*$D$7 -> 11804100 | F30: =F21*$D$7 -> 12176400 | G30: =G21*$D$7 -> 7774500 | H30: =H21*$D$7 -> 5737800 | I30: =I21*$D$7 -> 12023100 | ... M30: =M21*$D$7 -> 5759700 | N30: =SUM(B30:M30) -> 118698000
A31: Medium Döner Combo | B31: =B22*$D$8 -> 33654000 | C31: =C22*$D$8 -> 53534000 | D31: =D22*$D$8 -> 48052800 | E31: =E22*$D$8 -> 57368000 | F31: =F22*$D$8 -> 59270800 | G31: =G22*$D$8 -> 37857200 | H31: =H22*$D$8 -> 27917200 | I31: =I22*$D$8 -> 58504000 | ... M31: =M22*$D$8 -> 27860400 | N31: =SUM(B31:M31) -> 577258400
A32: Large Döner | B32: =B23*$D$9 -> 7048400 | C32: =C23*$D$9 -> 11229200 | D32: =D23*$D$9 -> 10076800 | E32: =E23*$D$9 -> 12033200 | F32: =F23*$D$9 -> 12435200 | G32: =G23*$D$9 -> 7932800 | H32: =H23*$D$9 -> 5842400 | I32: =I23*$D$9 -> 12274400 | ... M32: =M23*$D$9 -> 5842400 | N32: =SUM(B32:M32) -> 121055600
A33: Large Döner Combo | B33: =B24*$D$10 -> 13351000 | C33: =C24*$D$10 -> 21226400 | D33: =D24*$D$10 -> 19063200 | E33: =E24*$D$10 -> 22747400 | F33: =F24*$D$10 -> 23524800 | G33: =G24*$D$10 -> 15007200 | H33: =H24*$D$10 -> 11086400 | I33: =I24*$D$10 -> 23220600 | ... M33: =M24*$D$10 -> 11086400 | N33: =SUM(B33:M33) -> 229028800
A34: Total ventas brutas | B34: =SUM(B28:B33) -> 70683500 | C34: =SUM(C28:C33) -> 112454600 | D34: =SUM(D28:D33) -> 100940000 | E34: =SUM(E28:E33) -> 120508400 | F34: =SUM(F28:F33) -> 124516100 | G34: =SUM(G28:G33) -> 79491600 | H34: =SUM(H28:H33) -> 58633900 | I34: =SUM(I28:I33) -> 122906300 | ... N34: =SUM(N28:N33) -> 1212634600
A36: COSTO DE MATERIA PRIMA POR MES (COP) | B36: Jan | C36: Feb | D36: Mar | E36: Apr | F36: May | G36: Jun | H36: Jul | I36: Aug | J36: Sep | K36: Oct | L36: Nov | M36: Dec | N36: Total 2026
A37: Small Döner | B37: =B19*$G$5 -> 1997748 | C37: =C19*$G$5 -> 3171780 | D37: =D19*$G$5 -> 2849868 | E37: =E19*$G$5 -> 3399012 | F37: =F19*$G$5 -> 3512628 | G37: =G19*$G$5 -> 2243916 | H37: =H19*$G$5 -> 1656900 | I37: =I19*$G$5 -> 3465288 | ... M37: =M19*$G$5 -> 1656900 | N37: =SUM(B37:M37) -> 34217352
A38: Small Döner Combo | B38: =B20*$G$6 -> 3378498 | C38: =C20*$G$6 -> 5382474 | D38: =D20*$G$6 -> 4830096 | E38: =E20*$G$6 -> 5767854 | F38: =F20*$G$6 -> 5960544 | G38: =G20*$G$6 -> 3802416 | H38: =H20*$G$6 -> 2800428 | I38: =I20*$G$6 -> 5883468 | ... M38: =M20*$G$6 -> 2800428 | N38: =SUM(B38:M38) -> 58025382
A39: Medium Döner | B39: =B21*$G$7 -> 3831816 | C39: =C21*$G$7 -> 6099378 | D39: =D21*$G$7 -> 5468826 | E39: =E21*$G$7 -> 6535914 | F39: =F21*$G$7 -> 6742056 | G39: =G21*$G$7 -> 4304730 | H39: =H21*$G$7 -> 3177012 | I39: =I21*$G$7 -> 6657174 | ... M39: =M21*$G$7 -> 3189138 | N39: =SUM(B39:M39) -> 65722920
A40: Medium Döner Combo | B40: =B22*$G$8 -> 18634125 | C40: =C22*$G$8 -> 29641625 | D40: =D22*$G$8 -> 26606700 | E40: =E22*$G$8 -> 31764500 | F40: =F22*$G$8 -> 32818075 | G40: =G22*$G$8 -> 20961425 | H40: =H22*$G$8 -> 15457675 | I40: =I22*$G$8 -> 32393500 | ... M40: =M22*$G$8 -> 15426225 | N40: =SUM(B40:M40) -> 319626350
A41: Large Döner | B41: =B23*$G$9 -> 3902657 | C41: =C23*$G$9 -> 6217541 | D41: =D23*$G$9 -> 5579464 | E41: =E23*$G$9 -> 6662711 | F41: =F23*$G$9 -> 6885296 | G41: =G23*$G$9 -> 4392344 | H41: =H23*$G$9 -> 3234902 | I41: =I23*$G$9 -> 6796262 | ... M41: =M23*$G$9 -> 3234902 | N41: =SUM(B41:M41) -> 67027763
A42: Large Döner Combo | B42: =B24*$G$10 -> 7392425 | C42: =C24*$G$10 -> 11753020 | D42: =D24*$G$10 -> 10555260 | E42: =E24*$G$10 -> 12595195 | F42: =F24*$G$10 -> 13025640 | G42: =G24*$G$10 -> 8309460 | H42: =H24*$G$10 -> 6138520 | I42: =I24*$G$10 -> 12857205 | ... M42: =M24*$G$10 -> 6138520 | N42: =SUM(B42:M42) -> 126812840
A43: Total costo materia prima | B43: =SUM(B37:B42) -> 39137269 | C43: =SUM(C37:C42) -> 62265818 | D43: =SUM(D37:D42) -> 55890214 | E43: =SUM(E37:E42) -> 66725186 | F43: =SUM(F37:F42) -> 68944239 | G43: =SUM(G37:G42) -> 44014291 | H43: =SUM(H37:H42) -> 32465437 | I43: =SUM(I37:I42) -> 68052897 | ... N43: =SUM(N37:N42) -> 671432607
A45: Control: ventas anuales del detalle mensual = tabla de productos | E45: =IF(ABS(N34-E11)<1,"OK","REVISAR") -> OK

Sheet Estado de Resultados 2026
A1: Line | B1: Jan | C1: Feb | D1: Mar | E1: Apr | F1: May | G1: Jun | H1: Jul | I1: Aug | J1: Sep | K1: Oct | L1: Nov | M1: Dec | N1: Annual 2026
A2: Unidades vendidas (todos los productos) | B2: ='Ventas por Producto 2026'!B25 -> 2633 | C2: ='Ventas por Producto 2026'!C25 -> 4189 | D2: ='Ventas por Producto 2026'!D25 -> 3760 | E2: ='Ventas por Producto 2026'!E25 -> 4489 | F2: ='Ventas por Producto 2026'!F25 -> 4638 | G2: ='Ventas por Producto 2026'!G25 -> 2961 | H2: ='Ventas por Producto 2026'!H25 -> 2184 | I2: ='Ventas por Producto 2026'!I25 -> 4578 | ... M2: ='Ventas por Producto 2026'!M25 -> 2183 | N2: =SUM(B2:M2) -> 45170
A3: INGRESOS OPERACIONALES
A4: Ventas Small Döner | B4: ='Ventas por Producto 2026'!B28 -> 3608100 | C4: ='Ventas por Producto 2026'!C28 -> 5728500 | D4: ='Ventas por Producto 2026'!D28 -> 5147100 | E4: ='Ventas por Producto 2026'!E28 -> 6138900 | F4: ='Ventas por Producto 2026'!F28 -> 6344100 | G4: ='Ventas por Producto 2026'!G28 -> 4052700 | H4: ='Ventas por Producto 2026'!H28 -> 2992500 | I4: ='Ventas por Producto 2026'!I28 -> 6258600 | ... M4: ='Ventas por Producto 2026'!M28 -> 2992500 | N4: =SUM(B4:M4) -> 61799400
A5: Ventas Small Döner Combo | B5: ='Ventas por Producto 2026'!B29 -> 6101600 | C5: ='Ventas por Producto 2026'!C29 -> 9720800 | D5: ='Ventas por Producto 2026'!D29 -> 8723200 | E5: ='Ventas por Producto 2026'!E29 -> 10416800 | F5: ='Ventas por Producto 2026'!F29 -> 10764800 | G5: ='Ventas por Producto 2026'!G29 -> 6867200 | H5: ='Ventas por Producto 2026'!H29 -> 5057600 | I5: ='Ventas por Producto 2026'!I29 -> 10625600 | ... M5: ='Ventas por Producto 2026'!M29 -> 5057600 | N5: =SUM(B5:M5) -> 104794400
A6: Ventas Medium Döner | B6: ='Ventas por Producto 2026'!B30 -> 6920400 | C6: ='Ventas por Producto 2026'!C30 -> 11015700 | D6: ='Ventas por Producto 2026'!D30 -> 9876900 | E6: ='Ventas por Producto 2026'!E30 -> 11804100 | F6: ='Ventas por Producto 2026'!F30 -> 12176400 | G6: ='Ventas por Producto 2026'!G30 -> 7774500 | H6: ='Ventas por Producto 2026'!H30 -> 5737800 | I6: ='Ventas por Producto 2026'!I30 -> 12023100 | ... M6: ='Ventas por Producto 2026'!M30 -> 5759700 | N6: =SUM(B6:M6) -> 118698000
A7: Ventas Medium Döner Combo | B7: ='Ventas por Producto 2026'!B31 -> 33654000 | C7: ='Ventas por Producto 2026'!C31 -> 53534000 | D7: ='Ventas por Producto 2026'!D31 -> 48052800 | E7: ='Ventas por Producto 2026'!E31 -> 57368000 | F7: ='Ventas por Producto 2026'!F31 -> 59270800 | G7: ='Ventas por Producto 2026'!G31 -> 37857200 | H7: ='Ventas por Producto 2026'!H31 -> 27917200 | I7: ='Ventas por Producto 2026'!I31 -> 58504000 | ... M7: ='Ventas por Producto 2026'!M31 -> 27860400 | N7: =SUM(B7:M7) -> 577258400
A8: Ventas Large Döner | B8: ='Ventas por Producto 2026'!B32 -> 7048400 | C8: ='Ventas por Producto 2026'!C32 -> 11229200 | D8: ='Ventas por Producto 2026'!D32 -> 10076800 | E8: ='Ventas por Producto 2026'!E32 -> 12033200 | F8: ='Ventas por Producto 2026'!F32 -> 12435200 | G8: ='Ventas por Producto 2026'!G32 -> 7932800 | H8: ='Ventas por Producto 2026'!H32 -> 5842400 | I8: ='Ventas por Producto 2026'!I32 -> 12274400 | ... M8: ='Ventas por Producto 2026'!M32 -> 5842400 | N8: =SUM(B8:M8) -> 121055600
A9: Ventas Large Döner Combo | B9: ='Ventas por Producto 2026'!B33 -> 13351000 | C9: ='Ventas por Producto 2026'!C33 -> 21226400 | D9: ='Ventas por Producto 2026'!D33 -> 19063200 | E9: ='Ventas por Producto 2026'!E33 -> 22747400 | F9: ='Ventas por Producto 2026'!F33 -> 23524800 | G9: ='Ventas por Producto 2026'!G33 -> 15007200 | H9: ='Ventas por Producto 2026'!H33 -> 11086400 | I9: ='Ventas por Producto 2026'!I33 -> 23220600 | ... M9: ='Ventas por Producto 2026'!M33 -> 11086400 | N9: =SUM(B9:M9) -> 229028800
A10: Ventas brutas (total) | B10: =SUM(B4:B9) -> 70683500 | C10: =SUM(C4:C9) -> 112454600 | D10: =SUM(D4:D9) -> 100940000 | E10: =SUM(E4:E9) -> 120508400 | F10: =SUM(F4:F9) -> 124516100 | G10: =SUM(G4:G9) -> 79491600 | H10: =SUM(H4:H9) -> 58633900 | I10: =SUM(I4:I9) -> 122906300 | ... M10: =SUM(M4:M9) -> 58599000 | N10: =SUM(B10:M10) -> 1212634600
A11: (-) Devoluciones y descuentos (garantías, 3.4.3) | B11: =ROUND(B10*'Supuestos y Notas'!$B$4,0) -> 212051 | C11: =ROUND(C10*'Supuestos y Notas'!$B$4,0) -> 337364 | D11: =ROUND(D10*'Supuestos y Notas'!$B$4,0) -> 302820 | E11: =ROUND(E10*'Supuestos y Notas'!$B$4,0) -> 361525 | F11: =ROUND(F10*'Supuestos y Notas'!$B$4,0) -> 373548 | G11: =ROUND(G10*'Supuestos y Notas'!$B$4,0) -> 238475 | H11: =ROUND(H10*'Supuestos y Notas'!$B$4,0) -> 175902 | I11: =ROUND(I10*'Supuestos y Notas'!$B$4,0) -> 368719 | ... M11: =ROUND(M10*'Supuestos y Notas'!$B$4,0) -> 175797 | N11: =SUM(B11:M11) -> 3637904
A12: Ventas netas | B12: =B10-B11 -> 70471449 | C12: =C10-C11 -> 112117236 | D12: =D10-D11 -> 100637180 | E12: =E10-E11 -> 120146875 | F12: =F10-F11 -> 124142552 | G12: =G10-G11 -> 79253125 | H12: =H10-H11 -> 58457998 | I12: =I10-I11 -> 122537581 | ... M12: =M10-M11 -> 58423203 | N12: =SUM(B12:M12) -> 1208996696
A13: COSTO DE VENTAS
A14: Insumos / materia prima (según mezcla de productos) | B14: ='Ventas por Producto 2026'!B43 -> 39137269 | C14: ='Ventas por Producto 2026'!C43 -> 62265818 | D14: ='Ventas por Producto 2026'!D43 -> 55890214 | E14: ='Ventas por Producto 2026'!E43 -> 66725186 | F14: ='Ventas por Producto 2026'!F43 -> 68944239 | G14: ='Ventas por Producto 2026'!G43 -> 44014291 | H14: ='Ventas por Producto 2026'!H43 -> 32465437 | I14: ='Ventas por Producto 2026'!I43 -> 68052897 | ... M14: ='Ventas por Producto 2026'!M43 -> 32446113 | N14: =SUM(B14:M14) -> 671432607
A15: Mano de obra directa (6 Store Associates, fija) | B15: =ROUND('Supuestos y Notas'!$B$11/12,0) -> 15600000 | C15: =ROUND('Supuestos y Notas'!$B$11/12,0) -> 15600000 | D15: =ROUND('Supuestos y Notas'!$B$11/12,0) -> 15600000 | E15: =ROUND('Supuestos y Notas'!$B$11/12,0) -> 15600000 | F15: =ROUND('Supuestos y Notas'!$B$11/12,0) -> 15600000 | G15: =ROUND('Supuestos y Notas'!$B$11/12,0) -> 15600000 | H15: =ROUND('Supuestos y Notas'!$B$11/12,0) -> 15600000 | I15: =ROUND('Supuestos y Notas'!$B$11/12,0) -> 15600000 | ... L15: =ROUND('Supuestos y Notas'!$B$11/12,0) -> 15600000 | M15: ='Supuestos y Notas'!$B$11-SUM(B15:L15) -> 15600000 | N15: =SUM(B15:M15) -> 187200000
A16: Costos indirectos de producción (CIF) | B16: =B2*'Supuestos y Notas'!$B$9 -> 2633000 | C16: =C2*'Supuestos y Notas'!$B$9 -> 4189000 | D16: =D2*'Supuestos y Notas'!$B$9 -> 3760000 | E16: =E2*'Supuestos y Notas'!$B$9 -> 4489000 | F16: =F2*'Supuestos y Notas'!$B$9 -> 4638000 | G16: =G2*'Supuestos y Notas'!$B$9 -> 2961000 | H16: =H2*'Supuestos y Notas'!$B$9 -> 2184000 | I16: =I2*'Supuestos y Notas'!$B$9 -> 4578000 | ... M16: =M2*'Supuestos y Notas'!$B$9 -> 2183000 | N16: =SUM(B16:M16) -> 45170000
A17: Total costo de ventas | B17: =SUM(B14:B16) -> 57370269 | C17: =SUM(C14:C16) -> 82054818 | D17: =SUM(D14:D16) -> 75250214 | E17: =SUM(E14:E16) -> 86814186 | F17: =SUM(F14:F16) -> 89182239 | G17: =SUM(G14:G16) -> 62575291 | H17: =SUM(H14:H16) -> 50249437 | I17: =SUM(I14:I16) -> 88230897 | ... M17: =SUM(M14:M16) -> 50229113 | N17: =SUM(B17:M17) -> 903802607
A18: Utilidad bruta | B18: =B12-B17 -> 13101180 | C18: =C12-C17 -> 30062418 | D18: =D12-D17 -> 25386966 | E18: =E12-E17 -> 33332689 | F18: =F12-F17 -> 34960313 | G18: =G12-G17 -> 16677834 | H18: =H12-H17 -> 8208561 | I18: =I12-I17 -> 34306684 | ... M18: =M12-M17 -> 8194090 | N18: =SUM(B18:M18) -> 305194089
A19: GASTOS OPERACIONALES DE ADMINISTRACIÓN
A20: Nómina administrativa (Store Manager) | B20: =ROUND('Supuestos y Notas'!$B$12/12,0) -> 3500000 | C20: =ROUND('Supuestos y Notas'!$B$12/12,0) -> 3500000 | D20: =ROUND('Supuestos y Notas'!$B$12/12,0) -> 3500000 | E20: =ROUND('Supuestos y Notas'!$B$12/12,0) -> 3500000 | F20: =ROUND('Supuestos y Notas'!$B$12/12,0) -> 3500000 | G20: =ROUND('Supuestos y Notas'!$B$12/12,0) -> 3500000 | H20: =ROUND('Supuestos y Notas'!$B$12/12,0) -> 3500000 | I20: =ROUND('Supuestos y Notas'!$B$12/12,0) -> 3500000 | ... L20: =ROUND('Supuestos y Notas'!$B$12/12,0) -> 3500000 | M20: ='Supuestos y Notas'!$B$12-SUM(B20:L20) -> 3500000 | N20: =SUM(B20:M20) -> 42000000
A21: Servicios públicos | B21: =ROUND('Supuestos y Notas'!$B$13/12,0) -> 3500000 | C21: =ROUND('Supuestos y Notas'!$B$13/12,0) -> 3500000 | D21: =ROUND('Supuestos y Notas'!$B$13/12,0) -> 3500000 | E21: =ROUND('Supuestos y Notas'!$B$13/12,0) -> 3500000 | F21: =ROUND('Supuestos y Notas'!$B$13/12,0) -> 3500000 | G21: =ROUND('Supuestos y Notas'!$B$13/12,0) -> 3500000 | H21: =ROUND('Supuestos y Notas'!$B$13/12,0) -> 3500000 | I21: =ROUND('Supuestos y Notas'!$B$13/12,0) -> 3500000 | ... L21: =ROUND('Supuestos y Notas'!$B$13/12,0) -> 3500000 | M21: ='Supuestos y Notas'!$B$13-SUM(B21:L21) -> 3500000 | N21: =SUM(B21:M21) -> 42000000
A22: Honorarios (contador externo) | B22: =ROUND('Supuestos y Notas'!$B$14/12,0) -> 4000000 | C22: =ROUND('Supuestos y Notas'!$B$14/12,0) -> 4000000 | D22: =ROUND('Supuestos y Notas'!$B$14/12,0) -> 4000000 | E22: =ROUND('Supuestos y Notas'!$B$14/12,0) -> 4000000 | F22: =ROUND('Supuestos y Notas'!$B$14/12,0) -> 4000000 | G22: =ROUND('Supuestos y Notas'!$B$14/12,0) -> 4000000 | H22: =ROUND('Supuestos y Notas'!$B$14/12,0) -> 4000000 | I22: =ROUND('Supuestos y Notas'!$B$14/12,0) -> 4000000 | ... L22: =ROUND('Supuestos y Notas'!$B$14/12,0) -> 4000000 | M22: ='Supuestos y Notas'!$B$14-SUM(B22:L22) -> 4000000 | N22: =SUM(B22:M22) -> 48000000
A23: Seguros | B23: =ROUND('Supuestos y Notas'!$B$15/12,0) -> 500000 | C23: =ROUND('Supuestos y Notas'!$B$15/12,0) -> 500000 | D23: =ROUND('Supuestos y Notas'!$B$15/12,0) -> 500000 | E23: =ROUND('Supuestos y Notas'!$B$15/12,0) -> 500000 | F23: =ROUND('Supuestos y Notas'!$B$15/12,0) -> 500000 | G23: =ROUND('Supuestos y Notas'!$B$15/12,0) -> 500000 | H23: =ROUND('Supuestos y Notas'!$B$15/12,0) -> 500000 | I23: =ROUND('Supuestos y Notas'!$B$15/12,0) -> 500000 | ... L23: =ROUND('Supuestos y Notas'!$B$15/12,0) -> 500000 | M23: ='Supuestos y Notas'!$B$15-SUM(B23:L23) -> 500000 | N23: =SUM(B23:M23) -> 6000000
A24: Software y sistemas (MIS) | B24: =ROUND('Supuestos y Notas'!$B$16/12,0) -> 380000 | C24: =ROUND('Supuestos y Notas'!$B$16/12,0) -> 380000 | D24: =ROUND('Supuestos y Notas'!$B$16/12,0) -> 380000 | E24: =ROUND('Supuestos y Notas'!$B$16/12,0) -> 380000 | F24: =ROUND('Supuestos y Notas'!$B$16/12,0) -> 380000 | G24: =ROUND('Supuestos y Notas'!$B$16/12,0) -> 380000 | H24: =ROUND('Supuestos y Notas'!$B$16/12,0) -> 380000 | I24: =ROUND('Supuestos y Notas'!$B$16/12,0) -> 380000 | ... L24: =ROUND('Supuestos y Notas'!$B$16/12,0) -> 380000 | M24: ='Supuestos y Notas'!$B$16-SUM(B24:L24) -> 380000 | N24: =SUM(B24:M24) -> 4560000
A25: Depreciación y amortización | B25: =ROUND('Supuestos y Notas'!$B$17/12,0) -> 1416667 | C25: =ROUND('Supuestos y Notas'!$B$17/12,0) -> 1416667 | D25: =ROUND('Supuestos y Notas'!$B$17/12,0) -> 1416667 | E25: =ROUND('Supuestos y Notas'!$B$17/12,0) -> 1416667 | F25: =ROUND('Supuestos y Notas'!$B$17/12,0) -> 1416667 | G25: =ROUND('Supuestos y Notas'!$B$17/12,0) -> 1416667 | H25: =ROUND('Supuestos y Notas'!$B$17/12,0) -> 1416667 | I25: =ROUND('Supuestos y Notas'!$B$17/12,0) -> 1416667 | ... L25: =ROUND('Supuestos y Notas'!$B$17/12,0) -> 1416667 | M25: ='Supuestos y Notas'!$B$17-SUM(B25:L25) -> 1416663 | N25: =SUM(B25:M25) -> 17000000
A26: Total gastos de administración | B26: =SUM(B20:B25) -> 13296667 | C26: =SUM(C20:C25) -> 13296667 | D26: =SUM(D20:D25) -> 13296667 | E26: =SUM(E20:E25) -> 13296667 | F26: =SUM(F20:F25) -> 13296667 | G26: =SUM(G20:G25) -> 13296667 | H26: =SUM(H20:H25) -> 13296667 | I26: =SUM(I20:I25) -> 13296667 | ... M26: =SUM(M20:M25) -> 13296663 | N26: =SUM(B26:M26) -> 159560000
A27: GASTOS OPERACIONALES DE VENTAS
A28: Marketing y publicidad | B28: =ROUND('Supuestos y Notas'!$B$18/12,0) -> 3966667 | C28: =ROUND('Supuestos y Notas'!$B$18/12,0) -> 3966667 | D28: =ROUND('Supuestos y Notas'!$B$18/12,0) -> 3966667 | E28: =ROUND('Supuestos y Notas'!$B$18/12,0) -> 3966667 | F28: =ROUND('Supuestos y Notas'!$B$18/12,0) -> 3966667 | G28: =ROUND('Supuestos y Notas'!$B$18/12,0) -> 3966667 | H28: =ROUND('Supuestos y Notas'!$B$18/12,0) -> 3966667 | I28: =ROUND('Supuestos y Notas'!$B$18/12,0) -> 3966667 | ... L28: =ROUND('Supuestos y Notas'!$B$18/12,0) -> 3966667 | M28: ='Supuestos y Notas'!$B$18-SUM(B28:L28) -> 3966663 | N28: =SUM(B28:M28) -> 47600000
A29: Comisiones plataformas de domicilios | B29: =ROUND(B12*'Supuestos y Notas'!$B$5*'Supuestos y Notas'!$B$6,0) -> 3382630 | C29: =ROUND(C12*'Supuestos y Notas'!$B$5*'Supuestos y Notas'!$B$6,0) -> 5381627 | D29: =ROUND(D12*'Supuestos y Notas'!$B$5*'Supuestos y Notas'!$B$6,0) -> 4830585 | E29: =ROUND(E12*'Supuestos y Notas'!$B$5*'Supuestos y Notas'!$B$6,0) -> 5767050 | F29: =ROUND(F12*'Supuestos y Notas'!$B$5*'Supuestos y Notas'!$B$6,0) -> 5958842 | G29: =ROUND(G12*'Supuestos y Notas'!$B$5*'Supuestos y Notas'!$B$6,0) -> 3804150 | H29: =ROUND(H12*'Supuestos y Notas'!$B$5*'Supuestos y Notas'!$B$6,0) -> 2805984 | I29: =ROUND(I12*'Supuestos y Notas'!$B$5*'Supuestos y Notas'!$B$6,0) -> 5881804 | ... M29: =ROUND(M12*'Supuestos y Notas'!$B$5*'Supuestos y Notas'!$B$6,0) -> 2804314 | N29: =SUM(B29:M29) -> 58031841
A30: Empaques de venta | B30: =ROUND(B2*'Supuestos y Notas'!$B$7*'Supuestos y Notas'!$B$8,0) -> 292263 | C30: =ROUND(C2*'Supuestos y Notas'!$B$7*'Supuestos y Notas'!$B$8,0) -> 464979 | D30: =ROUND(D2*'Supuestos y Notas'!$B$7*'Supuestos y Notas'!$B$8,0) -> 417360 | E30: =ROUND(E2*'Supuestos y Notas'!$B$7*'Supuestos y Notas'!$B$8,0) -> 498279 | F30: =ROUND(F2*'Supuestos y Notas'!$B$7*'Supuestos y Notas'!$B$8,0) -> 514818 | G30: =ROUND(G2*'Supuestos y Notas'!$B$7*'Supuestos y Notas'!$B$8,0) -> 328671 | H30: =ROUND(H2*'Supuestos y Notas'!$B$7*'Supuestos y Notas'!$B$8,0) -> 242424 | I30: =ROUND(I2*'Supuestos y Notas'!$B$7*'Supuestos y Notas'!$B$8,0) -> 508158 | ... M30: =ROUND(M2*'Supuestos y Notas'!$B$7*'Supuestos y Notas'!$B$8,0) -> 242313 | N30: =SUM(B30:M30) -> 5013870
A31: Total gastos de ventas | B31: =SUM(B28:B30) -> 7641560 | C31: =SUM(C28:C30) -> 9813273 | D31: =SUM(D28:D30) -> 9214612 | E31: =SUM(E28:E30) -> 10231996 | F31: =SUM(F28:F30) -> 10440327 | G31: =SUM(G28:G30) -> 8099488 | H31: =SUM(H28:H30) -> 7015075 | I31: =SUM(I28:I30) -> 10356629 | ... M31: =SUM(M28:M30) -> 7013290 | N31: =SUM(B31:M31) -> 110645711
A32: Utilidad operacional (EBIT) | B32: =B18-B26-B31 -> -7837047 | C32: =C18-C26-C31 -> 6952478 | D32: =D18-D26-D31 -> 2875687 | E32: =E18-E26-E31 -> 9804026 | F32: =F18-F26-F31 -> 11223319 | G32: =G18-G26-G31 -> -4718321 | H32: =H18-H26-H31 -> -12103181 | I32: =I18-I26-I31 -> 10653388 | ... M32: =M18-M26-M31 -> -12115863 | N32: =SUM(B32:M32) -> 34988378
A33: EBITDA | B33: =B32+B25 -> -6420380 | C33: =C32+C25 -> 8369145 | D33: =D32+D25 -> 4292354 | E33: =E32+E25 -> 11220693 | F33: =F32+F25 -> 12639986 | G33: =G32+G25 -> -3301654 | H33: =H32+H25 -> -10686514 | I33: =I32+I25 -> 12070055 | ... M33: =M32+M25 -> -10699200 | N33: =SUM(B33:M33) -> 51988378
A34: PARTIDAS NO OPERACIONALES
A35: Gastos financieros (4x1000) | B35: =ROUND((B17+B26-B25+B31)*'Supuestos y Notas'!$B$19,0) -> 307567 | C35: =ROUND((C17+C26-C25+C31)*'Supuestos y Notas'!$B$19,0) -> 414992 | D35: =ROUND((D17+D26-D25+D31)*'Supuestos y Notas'!$B$19,0) -> 385379 | E35: =ROUND((E17+E26-E25+E31)*'Supuestos y Notas'!$B$19,0) -> 435705 | F35: =ROUND((F17+F26-F25+F31)*'Supuestos y Notas'!$B$19,0) -> 446010 | G35: =ROUND((G17+G26-G25+G31)*'Supuestos y Notas'!$B$19,0) -> 330219 | H35: =ROUND((H17+H26-H25+H31)*'Supuestos y Notas'!$B$19,0) -> 276578 | I35: =ROUND((I17+I26-I25+I31)*'Supuestos y Notas'!$B$19,0) -> 441870 | ... M35: =ROUND((M17+M26-M25+M31)*'Supuestos y Notas'!$B$19,0) -> 276490 | N35: =SUM(B35:M35) -> 4628032
A36: Utilidad antes de impuestos | B36: =B32-B35 -> -8144614 | C36: =C32-C35 -> 6537486 | D36: =D32-D35 -> 2490308 | E36: =E32-E35 -> 9368321 | F36: =F32-F35 -> 10777309 | G36: =G32-G35 -> -5048540 | H36: =H32-H35 -> -12379759 | I36: =I32-I35 -> 10211518 | ... M36: =M32-M35 -> -12392353 | N36: =SUM(B36:M36) -> 30360346
A37: Impuesto de renta (35% anual, provisionado) | B37: =ROUND($N$37/12,0) -> 885510 | C37: =ROUND($N$37/12,0) -> 885510 | D37: =ROUND($N$37/12,0) -> 885510 | E37: =ROUND($N$37/12,0) -> 885510 | F37: =ROUND($N$37/12,0) -> 885510 | G37: =ROUND($N$37/12,0) -> 885510 | H37: =ROUND($N$37/12,0) -> 885510 | I37: =ROUND($N$37/12,0) -> 885510 | ... L37: =ROUND($N$37/12,0) -> 885510 | M37: =$N$37-SUM(B37:L37) -> 885511 | N37: =ROUND(MAX(0,N36*'Supuestos y Notas'!$B$20),0) -> 10626121
A38: Utilidad neta | B38: =B36-B37 -> -9030124 | C38: =C36-C37 -> 5651976 | D38: =D36-D37 -> 1604798 | E38: =E36-E37 -> 8482811 | F38: =F36-F37 -> 9891799 | G38: =G36-G37 -> -5934050 | H38: =H36-H37 -> -13265269 | I38: =I36-I37 -> 9326008 | ... M38: =M36-M37 -> -13277864 | N38: =SUM(B38:M38) -> 19734225
A40: Ventas y unidades vienen de la hoja "Ventas por Producto 2026" (texto verde = vínculo a otra hoja).

Sheet Flujo de Efectivo 2026
A1: Line | B1: Jan | C1: Feb | D1: Mar | E1: Apr | F1: May | G1: Jun | H1: Jul | I1: Aug | J1: Sep | K1: Oct | L1: Nov | M1: Dec | N1: Annual 2026
A2: ACTIVIDADES DE OPERACIÓN
A3: Utilidad neta / (pérdida) | B3: ='Estado de Resultados 2026'!B38 -> -9030124 | C3: ='Estado de Resultados 2026'!C38 -> 5651976 | D3: ='Estado de Resultados 2026'!D38 -> 1604798 | E3: ='Estado de Resultados 2026'!E38 -> 8482811 | F3: ='Estado de Resultados 2026'!F38 -> 9891799 | G3: ='Estado de Resultados 2026'!G38 -> -5934050 | H3: ='Estado de Resultados 2026'!H38 -> -13265269 | I3: ='Estado de Resultados 2026'!I38 -> 9326008 | ... M3: ='Estado de Resultados 2026'!M38 -> -13277864 | N3: =SUM(B3:M3) -> 19734225
A4: Más: Depreciación | B4: ='Estado de Resultados 2026'!B25 -> 1416667 | C4: ='Estado de Resultados 2026'!C25 -> 1416667 | D4: ='Estado de Resultados 2026'!D25 -> 1416667 | E4: ='Estado de Resultados 2026'!E25 -> 1416667 | F4: ='Estado de Resultados 2026'!F25 -> 1416667 | G4: ='Estado de Resultados 2026'!G25 -> 1416667 | H4: ='Estado de Resultados 2026'!H25 -> 1416667 | I4: ='Estado de Resultados 2026'!I25 -> 1416667 | ... M4: ='Estado de Resultados 2026'!M25 -> 1416663 | N4: =SUM(B4:M4) -> 17000000
A5: (+/-) Nómina por pagar | B5: ='Balance General 2026'!B11 -> 2578500 | C5: ='Balance General 2026'!C11-'Balance General 2026'!B11 -> 0 | D5: ='Balance General 2026'!D11-'Balance General 2026'!C11 -> 0 | E5: ='Balance General 2026'!E11-'Balance General 2026'!D11 -> 0 | F5: ='Balance General 2026'!F11-'Balance General 2026'!E11 -> 0 | G5: ='Balance General 2026'!G11-'Balance General 2026'!F11 -> 0 | H5: ='Balance General 2026'!H11-'Balance General 2026'!G11 -> 0 | I5: ='Balance General 2026'!I11-'Balance General 2026'!H11 -> 0 | J5: ='Balance General 2026'!J11-'Balance General 2026'!I11 -> 0 | ... M5: ='Balance General 2026'!M11-'Balance General 2026'!L11 -> 0 | N5: =SUM(B5:M5) -> 2578500
A6: (+/-) Seguridad social por pagar | B6: ='Balance General 2026'!B12 -> 3915500 | C6: ='Balance General 2026'!C12-'Balance General 2026'!B12 -> 0 | D6: ='Balance General 2026'!D12-'Balance General 2026'!C12 -> 0 | E6: ='Balance General 2026'!E12-'Balance General 2026'!D12 -> 0 | F6: ='Balance General 2026'!F12-'Balance General 2026'!E12 -> 0 | G6: ='Balance General 2026'!G12-'Balance General 2026'!F12 -> 0 | H6: ='Balance General 2026'!H12-'Balance General 2026'!G12 -> 0 | I6: ='Balance General 2026'!I12-'Balance General 2026'!H12 -> 0 | J6: ='Balance General 2026'!J12-'Balance General 2026'!I12 -> 0 | ... M6: ='Balance General 2026'!M12-'Balance General 2026'!L12 -> 0 | N6: =SUM(B6:M6) -> 3915500
A7: (+/-) Impuestos por pagar | B7: ='Balance General 2026'!B13 -> 6501822 | C7: ='Balance General 2026'!C13-'Balance General 2026'!B13 -> 3579171 | D7: ='Balance General 2026'!D13-'Balance General 2026'!C13 -> -1042724 | E7: ='Balance General 2026'!E13-'Balance General 2026'!D13 -> 1653357 | F7: ='Balance General 2026'!F13-'Balance General 2026'!E13 -> 303644 | G7: ='Balance General 2026'!G13-'Balance General 2026'!F13 -> -3949453 | H7: ='Balance General 2026'!H13-'Balance General 2026'!G13 -> -1853140 | I7: ='Balance General 2026'!I13-'Balance General 2026'!H13 -> 5530898 | J7: ='Balance General 2026'!J13-'Balance General 2026'!I13 -> -251998 | ... M7: ='Balance General 2026'!M13-'Balance General 2026'!L13 -> 5881409 | N7: =SUM(B7:M7) -> 16123469
A8: Efectivo neto de operación | B8: =SUM(B3:B7) -> 5382365 | C8: =SUM(C3:C7) -> 10647814 | D8: =SUM(D3:D7) -> 1978741 | E8: =SUM(E3:E7) -> 11552835 | F8: =SUM(F3:F7) -> 11612110 | G8: =SUM(G3:G7) -> -8466836 | H8: =SUM(H3:H7) -> -13701742 | I8: =SUM(I3:I7) -> 16273573 | ... M8: =SUM(M3:M7) -> -5979792 | N8: =SUM(B8:M8) -> 59351694
A9: ACTIVIDADES DE INVERSIÓN
A10: Compra PP&E + inventario apertura (enero) | B10: =-'Supuestos y Notas'!$B$22 -> -90000000 | C10: 0 | D10: 0 | E10: 0 | F10: 0 | G10: 0 | H10: 0 | I10: 0 | J10: 0 | K10: 0 | L10: 0 | M10: 0 | N10: =SUM(B10:M10) -> -90000000
A11: ACTIVIDADES DE FINANCIACIÓN
A12: Aporte de capital social (apertura, enero) | B12: ='Supuestos y Notas'!$B$21 -> 130000000 | C12: 0 | D12: 0 | E12: 0 | F12: 0 | G12: 0 | H12: 0 | I12: 0 | J12: 0 | K12: 0 | L12: 0 | M12: 0 | N12: =SUM(B12:M12) -> 130000000
A13: Flujo neto del periodo | B13: =B8+B10+B12 -> 45382365 | C13: =C8+C10+C12 -> 10647814 | D13: =D8+D10+D12 -> 1978741 | E13: =E8+E10+E12 -> 11552835 | F13: =F8+F10+F12 -> 11612110 | G13: =G8+G10+G12 -> -8466836 | H13: =H8+H10+H12 -> -13701742 | I13: =I8+I10+I12 -> 16273573 | ... M13: =M8+M10+M12 -> -5979792 | N13: =SUM(B13:M13) -> 99351694
A14: Saldo final de efectivo | B14: =B13 -> 45382365 | C14: =B14+C13 -> 56030179 | D14: =C14+D13 -> 58008920 | E14: =D14+E13 -> 69561755 | F14: =E14+F13 -> 81173865 | G14: =F14+G13 -> 72707029 | H14: =G14+H13 -> 59005287 | I14: =H14+I13 -> 75278860 | J14: =I14+J13 -> 84926340 | ... M14: =L14+M13 -> 99351694 | N14: =M14 -> 99351694

Sheet Balance General 2026
A1: Line | B1: Jan | C1: Feb | D1: Mar | E1: Apr | F1: May | G1: Jun | H1: Jul | I1: Aug | J1: Sep | K1: Oct | L1: Nov | M1: Dec | N1: Annual 2026 (Dec 31)
A2: ACTIVO CORRIENTE
A3: Efectivo y equivalentes | B3: ='Flujo de Efectivo 2026'!B14 -> 45382365 | C3: ='Flujo de Efectivo 2026'!C14 -> 56030179 | D3: ='Flujo de Efectivo 2026'!D14 -> 58008920 | E3: ='Flujo de Efectivo 2026'!E14 -> 69561755 | F3: ='Flujo de Efectivo 2026'!F14 -> 81173865 | G3: ='Flujo de Efectivo 2026'!G14 -> 72707029 | H3: ='Flujo de Efectivo 2026'!H14 -> 59005287 | I3: ='Flujo de Efectivo 2026'!I14 -> 75278860 | ... M3: ='Flujo de Efectivo 2026'!M14 -> 99351694 | N3: =M3 -> 99351694
A4: Inventarios | B4: ='Supuestos y Notas'!$B$23 -> 5000000 | C4: ='Supuestos y Notas'!$B$23 -> 5000000 | D4: ='Supuestos y Notas'!$B$23 -> 5000000 | E4: ='Supuestos y Notas'!$B$23 -> 5000000 | F4: ='Supuestos y Notas'!$B$23 -> 5000000 | G4: ='Supuestos y Notas'!$B$23 -> 5000000 | H4: ='Supuestos y Notas'!$B$23 -> 5000000 | I4: ='Supuestos y Notas'!$B$23 -> 5000000 | ... M4: ='Supuestos y Notas'!$B$23 -> 5000000 | N4: =M4 -> 5000000
A5: Total activo corriente | B5: =B3+B4 -> 50382365 | C5: =C3+C4 -> 61030179 | D5: =D3+D4 -> 63008920 | E5: =E3+E4 -> 74561755 | F5: =F3+F4 -> 86173865 | G5: =G3+G4 -> 77707029 | H5: =H3+H4 -> 64005287 | I5: =I3+I4 -> 80278860 | ... M5: =M3+M4 -> 104351694 | N5: =M5 -> 104351694
A6: ACTIVO NO CORRIENTE
A7: Propiedad, planta y equipo, neto | B7: ='Supuestos y Notas'!$B$26-SUM('Estado de Resultados 2026'!$B$25:B$25) -> 83583333 | C7: ='Supuestos y Notas'!$B$26-SUM('Estado de Resultados 2026'!$B$25:C$25) -> 82166666 | D7: ='Supuestos y Notas'!$B$26-SUM('Estado de Resultados 2026'!$B$25:D$25) -> 80749999 | E7: ='Supuestos y Notas'!$B$26-SUM('Estado de Resultados 2026'!$B$25:E$25) -> 79333332 | F7: ='Supuestos y Notas'!$B$26-SUM('Estado de Resultados 2026'!$B$25:F$25) -> 77916665 | G7: ='Supuestos y Notas'!$B$26-SUM('Estado de Resultados 2026'!$B$25:G$25) -> 76499998 | H7: ='Supuestos y Notas'!$B$26-SUM('Estado de Resultados 2026'!$B$25:H$25) -> 75083331 | I7: ='Supuestos y Notas'!$B$26-SUM('Estado de Resultados 2026'!$B$25:I$25) -> 73666664 | ... M7: ='Supuestos y Notas'!$B$26-SUM('Estado de Resultados 2026'!$B$25:M$25) -> 68000000 | N7: =M7 -> 68000000
A8: Total activo no corriente | B8: =B7 -> 83583333 | C8: =C7 -> 82166666 | D8: =D7 -> 80749999 | E8: =E7 -> 79333332 | F8: =F7 -> 77916665 | G8: =G7 -> 76499998 | H8: =H7 -> 75083331 | I8: =I7 -> 73666664 | ... M8: =M7 -> 68000000 | N8: =M8 -> 68000000
A9: TOTAL ACTIVO | B9: =B5+B8 -> 133965698 | C9: =C5+C8 -> 143196845 | D9: =D5+D8 -> 143758919 | E9: =E5+E8 -> 153895087 | F9: =F5+F8 -> 164090530 | G9: =G5+G8 -> 154207027 | H9: =H5+H8 -> 139088618 | I9: =I5+I8 -> 153945524 | ... M9: =M5+M8 -> 172351694 | N9: =M9 -> 172351694
A10: PASIVO CORRIENTE
A11: Nómina por pagar y prestaciones sociales | B11: ='Supuestos y Notas'!$B$24 -> 2578500 | C11: ='Supuestos y Notas'!$B$24 -> 2578500 | D11: ='Supuestos y Notas'!$B$24 -> 2578500 | E11: ='Supuestos y Notas'!$B$24 -> 2578500 | F11: ='Supuestos y Notas'!$B$24 -> 2578500 | G11: ='Supuestos y Notas'!$B$24 -> 2578500 | H11: ='Supuestos y Notas'!$B$24 -> 2578500 | I11: ='Supuestos y Notas'!$B$24 -> 2578500 | ... M11: ='Supuestos y Notas'!$B$24 -> 2578500 | N11: =M11 -> 2578500
A12: Seguridad social y parafiscales por pagar | B12: ='Supuestos y Notas'!$B$25 -> 3915500 | C12: ='Supuestos y Notas'!$B$25 -> 3915500 | D12: ='Supuestos y Notas'!$B$25 -> 3915500 | E12: ='Supuestos y Notas'!$B$25 -> 3915500 | F12: ='Supuestos y Notas'!$B$25 -> 3915500 | G12: ='Supuestos y Notas'!$B$25 -> 3915500 | H12: ='Supuestos y Notas'!$B$25 -> 3915500 | I12: ='Supuestos y Notas'!$B$25 -> 3915500 | ... M12: ='Supuestos y Notas'!$B$25 -> 3915500 | N12: =M12 -> 3915500
A13: Impuestos por pagar (incl. renta 100% a dic 31) | B13: =ROUND('Estado de Resultados 2026'!B10*'Supuestos y Notas'!$B$31,0) -> 6501822 | C13: =ROUND('Estado de Resultados 2026'!C10*'Supuestos y Notas'!$B$32,0) -> 10080993 | D13: =ROUND('Estado de Resultados 2026'!D10*'Supuestos y Notas'!$B$33,0) -> 9038269 | E13: =ROUND('Estado de Resultados 2026'!E10*'Supuestos y Notas'!$B$34,0) -> 10691626 | F13: =ROUND('Estado de Resultados 2026'!F10*'Supuestos y Notas'!$B$35,0) -> 10995270 | G13: =ROUND('Estado de Resultados 2026'!G10*'Supuestos y Notas'!$B$36,0) -> 7045817 | H13: =ROUND('Estado de Resultados 2026'!H10*'Supuestos y Notas'!$B$37,0) -> 5192677 | I13: =ROUND('Estado de Resultados 2026'!I10*'Supuestos y Notas'!$B$38,0) -> 10723575 | J13: =ROUND('Estado de Resultados 2026'!J10*'Supuestos y Notas'!$B$39,0) -> 10471577 | K13: =ROUND('Estado de Resultados 2026'!K10*'Supuestos y Notas'!$B$40,0) -> 10775250 | L13: =ROUND('Estado de Resultados 2026'!L10*'Supuestos y Notas'!$B$41,0) -> 10242060 | M13: =ROUND('Estado de Resultados 2026'!M10*'Supuestos y Notas'!$B$42,0)+'Estado de Resultados 2026'!$N$37 -> 16123469 | N13: =M13 -> 16123469
A14: TOTAL PASIVO | B14: =SUM(B11:B13) -> 12995822 | C14: =SUM(C11:C13) -> 16574993 | D14: =SUM(D11:D13) -> 15532269 | E14: =SUM(E11:E13) -> 17185626 | F14: =SUM(F11:F13) -> 17489270 | G14: =SUM(G11:G13) -> 13539817 | H14: =SUM(H11:H13) -> 11686677 | I14: =SUM(I11:I13) -> 17217575 | ... M14: =SUM(M11:M13) -> 22617469 | N14: =M14 -> 22617469
A15: PATRIMONIO
A16: Capital social (100% equity, apertura) | B16: ='Supuestos y Notas'!$B$21 -> 130000000 | C16: ='Supuestos y Notas'!$B$21 -> 130000000 | D16: ='Supuestos y Notas'!$B$21 -> 130000000 | E16: ='Supuestos y Notas'!$B$21 -> 130000000 | F16: ='Supuestos y Notas'!$B$21 -> 130000000 | G16: ='Supuestos y Notas'!$B$21 -> 130000000 | H16: ='Supuestos y Notas'!$B$21 -> 130000000 | I16: ='Supuestos y Notas'!$B$21 -> 130000000 | ... M16: ='Supuestos y Notas'!$B$21 -> 130000000 | N16: =M16 -> 130000000
A17: Utilidades retenidas (acumuladas del año) | B17: =SUM('Estado de Resultados 2026'!$B$38:B$38) -> -9030124 | C17: =SUM('Estado de Resultados 2026'!$B$38:C$38) -> -3378148 | D17: =SUM('Estado de Resultados 2026'!$B$38:D$38) -> -1773350 | E17: =SUM('Estado de Resultados 2026'!$B$38:E$38) -> 6709461 | F17: =SUM('Estado de Resultados 2026'!$B$38:F$38) -> 16601260 | G17: =SUM('Estado de Resultados 2026'!$B$38:G$38) -> 10667210 | H17: =SUM('Estado de Resultados 2026'!$B$38:H$38) -> -2598059 | I17: =SUM('Estado de Resultados 2026'!$B$38:I$38) -> 6727949 | ... M17: =SUM('Estado de Resultados 2026'!$B$38:M$38) -> 19734225 | N17: =M17 -> 19734225
A18: TOTAL PATRIMONIO | B18: =B16+B17 -> 120969876 | C18: =C16+C17 -> 126621852 | D18: =D16+D17 -> 128226650 | E18: =E16+E17 -> 136709461 | F18: =F16+F17 -> 146601260 | G18: =G16+G17 -> 140667210 | H18: =H16+H17 -> 127401941 | I18: =I16+I17 -> 136727949 | ... M18: =M16+M17 -> 149734225 | N18: =M18 -> 149734225
A19: TOTAL PASIVO + PATRIMONIO | B19: =B14+B18 -> 133965698 | C19: =C14+C18 -> 143196845 | D19: =D14+D18 -> 143758919 | E19: =E14+E18 -> 153895087 | F19: =F14+F18 -> 164090530 | G19: =G14+G18 -> 154207027 | H19: =H14+H18 -> 139088618 | I19: =I14+I18 -> 153945524 | ... M19: =M14+M18 -> 172351694 | N19: =M19 -> 172351694
A21: Control: Activo − (Pasivo + Patrimonio) | B21: =B9-B19 -> 0 | C21: =C9-C19 -> 0 | D21: =D9-D19 -> 0 | E21: =E9-E19 -> 0 | F21: =F9-F19 -> 0 | G21: =G9-G19 -> 0 | H21: =H9-H19 -> 0 | I21: =I9-I19 -> 0 | ... M21: =M9-M19 -> 0 | N21: =M21 -> 0

Sheet Supuestos y Notas
A1: 2026 -- Year 1 Monthly Financial Model -- Döner Street
A3: PARÁMETROS DEL MODELO (celdas azules = datos de entrada editables)
A4: Devoluciones y descuentos (% de ventas brutas) | B4: 0.003 | C4: Garantías, 3.4.3 — tasa implícita del modelo original
A5: Participación de ventas por apps de domicilio | B5: 0.24 | C5: Supuesto original (nota 8)
A6: Comisión plataformas de domicilio | B6: 0.2 | C6: Supuesto original (nota 8)
A7: Participación domicilio + para llevar (usa empaque) | B7: 0.37 | C7: Supuesto original (nota 8)
A8: Costo de empaque por unidad (COP) | B8: 300 | C8: Supuesto original (nota 8)
A9: CIF por unidad (COP) | B9: 1000 | C9: Supuesto original, 3.4.2
A10: Costo materia prima Medium Döner Combo (COP) | B10: 15725 | C10: Supuesto original, 3.4.2
A11: Mano de obra directa anual (6 Store Associates) | B11: 187200000 | C11: Fija, supuesto original
A12: Nómina administrativa anual (Store Manager) | B12: 42000000 | C12: Supuesto original
A13: Servicios públicos anual | B13: 42000000 | C13: Supuesto original
A14: Honorarios contador anual | B14: 48000000 | C14: Supuesto original
A15: Seguros anual | B15: 6000000 | C15: Supuesto original
... A25: Seguridad social y parafiscales por pagar (saldo permanente) | B25: 3915500 | C25: Supuesto original
A26: PP&E bruto (compra − inventario) | B26: =$B$22-$B$23 -> 85000000 | C26: Calculado
A27: Food cost % (materia prima ÷ precio Medium Combo) | B27: =B10/'Ventas por Producto 2026'!D8 -> 0.55369718 | C27: Calculado — se aplica al precio de cada producto
A29: FACTOR DE IMPUESTOS INDIRECTOS POR PAGAR (% de ventas brutas del mes)
A30: Derivado del modelo original: saldo de impuestos por pagar ÷ ventas brutas de cada mes (en diciembre, sin la renta anual). Así el saldo se mueve con las ventas reales.
A31: Factor Jan | B31: 0.091985
A32: Factor Feb | B32: 0.089645
A33: Factor Mar | B33: 0.089541
A34: Factor Apr | B34: 0.088721
A35: Factor May | B35: 0.088304
A36: Factor Jun | B36: 0.088636
A37: Factor Jul | B37: 0.088561
A38: Factor Aug | B38: 0.08725
A39: Factor Sep | B39: 0.086895
A40: Factor Oct | B40: 0.086537
A41: Factor Nov | B41: 0.086157
A42: Factor Dec | B42: 0.093813
A44: NOTAS
A45: CORRECCIÓN (oct 2026): las ventas ya no se calculan como si todo fuera Medium Döner Combo a $28.400. Ahora se detallan los 6 productos (Small/Medium/Large Döner y sus combos) con su mezcla, unidades, precio y ventas — ver hoja "Ventas por Producto 2026".
A46: Unidades y precios por producto tomados de la tabla de ventas por producto del equipo (total 45.170 unidades, ventas brutas $1.212.634.600). Las unidades de cada producto se reparten mes a mes con la estacionalidad del calendario 2026 (150/90/40 combos/día en temporada alta/baja/muerta).
A47: Costo de materia prima por producto: el modelo solo tenía el costo del Medium Combo ($15.725). Para los demás se aplica el mismo food cost % (15.725 ÷ 28.400 = 55,4%) a su precio. Si tienen el costeo real de cada receta, reemplacen la columna "Costo materia prima unitario".
A48: CORRECCIÓN 2: en el flujo de febrero se restaban $6.494.000 de nómina y seguridad social por pagar, pero el balance los seguía mostrando sin sumarlos en el Total Pasivo. Ahora esos saldos se mantienen permanentes (se causan y se pagan cada mes), el Total Pasivo los incluye y el balance cuadra todos los meses.
A49: 2026 is Döner Street's Grand Opening and first full year of operation; the 2027 three-scenario model (Estados_Financieros_Doner_Street_2027.xlsx) is the second-year outlook and was left as originally built.
A50: This model is independent of 2027 -- it is not the 2027 annual total prorated to months. It reapplies the same first-principles assumptions (daily volume by season, per-unit costs, fixed payroll/overhead, the 35% Medium Combo price-plus methodology) to the actual 2026 calendar.
A51: Daily volumes: 150 combos/day high season, 90 low season, 40 dead season (Realistic case, 3.5.1), mapped day-by-day onto 2026's specific season dates (3.4.4 Seasons, DD/MM windows applied to the 2026 calendar).
A52: Price $28,400, materials $15,725/unit, CIF $1,000/unit (3.4.2). Direct labor fixed $187,200,000/yr (6 Store Associates). Admin payroll, honorarios, seguros, software, utilities, depreciation, and marketing are annual totals spread evenly across the 12 months.
...
