Workbook

Sheet Campaigns
A1: Area | B1: Tasks | C1: Start Date | D1: Duration Days | E1: End Date
A2: Grand Opening | B2: Teaser countdown on Instagram & TikTok (“something is spinning on Calle 72”) | C2: 46391 | D2: 14 | E2: =C2+D2
B3: Press release to Bogotá food blogs and neighborhood groups | C3: 46398 | D3: 14 | E3: =C3+D3
B4: Grand opening week: free soft drink with any Combo | C4: 46405 | D4: 7 | E4: =C4+D4
B5: Flyers & free tastings at nearby offices and universities | C5: 46405 | D5: 14 | E5: =C5+D5
B6: Announce the Customer Satisfaction Guarantee (counter signage + social post) | C6: 46405 | D6: 7 | E6: =C6+D6
A7: Digital Advertising | B7: Always-on content on Instagram, TikTok & Facebook (product videos, behind the counter, combos) | C7: 46391 | D7: =$C$52-C7 | E7: =C7+D7
B8: Google Business Profile: photos, hours, menu and review requests | C8: 46391 | D8: =$C$52-C8 | E8: =C8+D8
B9: Paid geo-targeted Meta Ads (radius around the store) | C9: 46405 | D9: =$C$52-C9 | E9: =C9+D9
B10: Food micro-influencer & blogger collaborations in Bogotá — wave 1 | C10: 46419 | D10: 28 | E10: =C10+D10
B11: QR code on packaging and receipts: follow us + 10% off the next order | C11: 46433 | D11: =$C$52-C11 | E11: =C11+D11
B12: WhatsApp Business catalog and weekly offer broadcast | C12: 46440 | D12: =$C$52-C12 | E12: =C12+D12
B13: Monthly customer photo contest (#DonerHouse): winner gets a free Combo | C13: 46482 | D13: 182 | E13: =C13+D13
B14: Food micro-influencer & blogger collaborations in Bogotá — wave 2 (second semester) | C14: 46601 | D14: 28 | E14: =C14+D14
B15: TikTok challenge: “the perfect wrap” video with a prize | C15: 46657 | D15: 21 | E15: =C15+D15
A16: Delivery & Loyalty | B16: Launch on Rappi, Uber Eats & DiDi Food with an introductory discount | C16: 46412 | D16: 28 | E16: =C16+D16
B17: Loyalty card: every 10th döner is free | C17: 46419 | D17: =$C$52-C17 | E17: =C17+D17
B18: Student & office-worker discount, first semester (10% with ID or work badge) | C18: 46419 | D18: 119 | E18: =C18+D18
B19: Payday weekends (15th and 30th): Combo upgrade to the next size | C19: 46447 | D19: =$C$52-C19 | E19: =C19+D19
B20: Corporate lunch plan: bulk orders for nearby offices via WhatsApp | C20: 46461 | D20: =$C$52-C20 | E20: =C20+D20
B21: Refer-a-friend: both get free fries on their next order | C21: 46489 | D21: 84 | E21: =C21+D21
B22: Student & office-worker discount, second semester (10% with ID or work badge) | C22: 46601 | D22: 119 | E22: =C22+D22
B23: Rainy-season delivery push: free drink on delivery orders on rainy days | C23: 46678 | D23: 42 | E23: =C23+D23
B24: Double loyalty stamps in December | C24: 46727 | D24: 21 | E24: =C24+D24
A25: Seasonal Dates | B25: Valentine's Day (14 Feb): “Share a Döner”, 2 Combos with 20% off | C25: 46426 | D25: 7 | E25: =C25+D25
B26: Mother's Day (9 May): Family Combo pack | C26: 46510 | D26: 7 | E26: =C26+D26
B27: Father's Day (20 Jun): Large Döner Combo at a special price | C27: 46552 | D27: 7 | E27: =C27+D27
B28: Six-month anniversary (4 Jul): free size upgrade all week | C28: 46573 | D28: 7 | E28: =C28+D28
B29: Amor y Amistad (18 Sep): Friends Combo, 3 Combos with 15% off | C29: 46643 | D29: 7 | E29: =C29+D29
B30: Long weekend (18 Oct): delivery-app free-fries promo | C30: 46671 | D30: 14 | E30: =C30+D30
B31: Halloween (31 Oct): themed combo and social costume contest | C31: 46685 | D31: 7 | E31: =C31+D31
B32: Long weekend (15 Nov): delivery-app free-fries promo | C32: 46699 | D32: 14 | E32: =C32+D32
B33: Black Friday (26 Nov): one-day Combo deal, delivery apps and store | C33: 46713 | D33: 7 | E33: =C33+D33
B34: Christmas & year-end: Party Pack for office and family gatherings | C34: 46734 | D34: 14 | E34: =C34+D34
A35: Community & Partnerships | B35: First-semester welcome week: campus stand with free samples | C35: 46419 | D35: 7 | E35: =C35+D35
B36: Partnerships with nearby gyms and coworking spaces (show your badge, get a Combo deal) | C36: 46454 | D36: 84 | E36: =C36+D36
B37: Neighborhood tasting day: live döner-carving show on Calle 72 | C37: 46524 | D37: 7 | E37: =C37+D37
B38: Second-semester welcome week: campus stand with free samples | C38: 46601 | D38: 7 | E38: =C38+D38
B39: Sponsor a local amateur football tournament: team Combo packs | C39: 46615 | D39: 28 | E39: =C39+D39
B40: Community giving: one döner donated to a local food bank for every 10 sold | C40: 46664 | D40: 28 | E40: =C40+D40
...

Sheet Gantt Chart
A1: Area | B1: Campaign | C1: Start | D1: End | E1: January | I1: February | M1: March | R1: April | V1: May | AA1: June | AE1: July | AI1: August | AN1: September | AR1: October | AV1: November | BA1: December
E2: 46391 | F2: 46398 | G2: 46405 | H2: 46412 | I2: 46419 | J2: 46426 | K2: 46433 | L2: 46440 | M2: 46447 | N2: 46454 | O2: 46461 | P2: 46468 | Q2: 46475 | R2: 46482 | S2: 46489 | T2: 46496 | U2: 46503 | V2: 46510 | W2: 46517 | X2: 46524 | Y2: 46531 | Z2: 46538 | AA2: 46545 | AB2: 46552 | AC2: 46559 | AD2: 46566 | AE2: 46573 | AF2: 46580 | AG2: 46587 | AH2: 46594 | AI2: 46601 | AJ2: 46608 | AK2: 46615 | AL2: 46622 | AM2: 46629 | AN2: 46636 | AO2: 46643 | AP2: 46650 | AQ2: 46657 | AR2: 46664 | AS2: 46671 | AT2: 46678 | AU2: 46685 | AV2: 46692 | AW2: 46699 | AX2: 46706 | AY2: 46713 | AZ2: 46720 | BA2: 46727 | BB2: 46734 | BC2: 46741 | BD2: 46748
A3: Season of each week (editable) | E3: Low | F3: Low | G3: Low | H3: Low | I3: High | J3: High | K3: High | L3: High | M3: High | N3: High | O3: High | P3: Dead | Q3: High | R3: High | S3: High | T3: High | U3: High | V3: High | W3: High | X3: High | Y3: High | Z3: High | AA3: Low | AB3: Low | AC3: Low | AD3: Dead | AE3: Dead | AF3: Low | AG3: Low | AH3: Low | AI3: High | AJ3: High | AK3: High | AL3: High | AM3: High | AN3: High | AO3: High | AP3: High | AQ3: High | AR3: High | AS3: High | AT3: High | AU3: High | AV3: High | AW3: High | AX3: High | AY3: High | AZ3: Low | BA3: Low | BB3: Low | BC3: Dead | BD3: Dead
A4: Grand Opening | B4: =Campaigns!B2 | C4: =Campaigns!C2 | D4: =Campaigns!E2
B5: =Campaigns!B3 | C5: =Campaigns!C3 | D5: =Campaigns!E3
B6: =Campaigns!B4 | C6: =Campaigns!C4 | D6: =Campaigns!E4
B7: =Campaigns!B5 | C7: =Campaigns!C5 | D7: =Campaigns!E5
B8: =Campaigns!B6 | C8: =Campaigns!C6 | D8: =Campaigns!E6
A9: Digital Advertising | B9: =Campaigns!B7 | C9: =Campaigns!C7 | D9: =Campaigns!E7
B10: =Campaigns!B8 | C10: =Campaigns!C8 | D10: =Campaigns!E8
B11: =Campaigns!B9 | C11: =Campaigns!C9 | D11: =Campaigns!E9
B12: =Campaigns!B10 | C12: =Campaigns!C10 | D12: =Campaigns!E10
B13: =Campaigns!B11 | C13: =Campaigns!C11 | D13: =Campaigns!E11
B14: =Campaigns!B12 | C14: =Campaigns!C12 | D14: =Campaigns!E12
B15: =Campaigns!B13 | C15: =Campaigns!C13 | D15: =Campaigns!E13
B16: =Campaigns!B14 | C16: =Campaigns!C14 | D16: =Campaigns!E14
B17: =Campaigns!B15 | C17: =Campaigns!C15 | D17: =Campaigns!E15
A18: Delivery & Loyalty | B18: =Campaigns!B16 | C18: =Campaigns!C16 | D18: =Campaigns!E16
B19: =Campaigns!B17 | C19: =Campaigns!C17 | D19: =Campaigns!E17
B20: =Campaigns!B18 | C20: =Campaigns!C18 | D20: =Campaigns!E18
B21: =Campaigns!B19 | C21: =Campaigns!C19 | D21: =Campaigns!E19
B22: =Campaigns!B20 | C22: =Campaigns!C20 | D22: =Campaigns!E20
B23: =Campaigns!B21 | C23: =Campaigns!C21 | D23: =Campaigns!E21
B24: =Campaigns!B22 | C24: =Campaigns!C22 | D24: =Campaigns!E22
B25: =Campaigns!B23 | C25: =Campaigns!C23 | D25: =Campaigns!E23
B26: =Campaigns!B24 | C26: =Campaigns!C24 | D26: =Campaigns!E24
A27: Seasonal Dates | B27: =Campaigns!B25 | C27: =Campaigns!C25 | D27: =Campaigns!E25
B28: =Campaigns!B26 | C28: =Campaigns!C26 | D28: =Campaigns!E26
B29: =Campaigns!B27 | C29: =Campaigns!C27 | D29: =Campaigns!E27
B30: =Campaigns!B28 | C30: =Campaigns!C28 | D30: =Campaigns!E28
B31: =Campaigns!B29 | C31: =Campaigns!C29 | D31: =Campaigns!E29
B32: =Campaigns!B30 | C32: =Campaigns!C30 | D32: =Campaigns!E30
B33: =Campaigns!B31 | C33: =Campaigns!C31 | D33: =Campaigns!E31
B34: =Campaigns!B32 | C34: =Campaigns!C32 | D34: =Campaigns!E32
B35: =Campaigns!B33 | C35: =Campaigns!C33 | D35: =Campaigns!E33
B36: =Campaigns!B34 | C36: =Campaigns!C34 | D36: =Campaigns!E34
A37: Community & Partnerships | B37: =Campaigns!B35 | C37: =Campaigns!C35 | D37: =Campaigns!E35
B38: =Campaigns!B36 | C38: =Campaigns!C36 | D38: =Campaigns!E36
B39: =Campaigns!B37 | C39: =Campaigns!C37 | D39: =Campaigns!E37
B40: =Campaigns!B38 | C40: =Campaigns!C38 | D40: =Campaigns!E38
...
